Workbook

Sheet Daily
A1: Date | B1: 3m | C1: 6m | D1: 12m | E1: 24m | F1: 36m | G1: 48m | H1: 60m | I1: 72m | J1: 84m | K1: 96m | L1: 108m | M1: 120m | N1: 132m | O1: 144m | P1: 156m | Q1: 168m | R1: 180m | S1: 192m | T1: 204m | U1: 216m | V1: 228m | W1: 240m
A2: 40273 | B2: 2.46 | C2: 4.56 | D2: 5.68 | E2: 6.59 | F2: 6.9 | G2: 7.08 | H2: 7.25 | I2: 7.41 | J2: 7.55 | K2: 7.69 | L2: 7.8 | M2: 7.9 | N2: 7.98 | O2: 8.06 | P2: 8.12 | Q2: 8.17 | R2: 8.22 | S2: 8.26 | T2: 8.3 | U2: 8.33 | V2: 8.36 | W2: 8.38
A3: 40274 | B3: 2.9 | C3: 4.26 | D3: 5.14 | E3: 6.14 | F3: 6.67 | G3: 7.01 | H3: 7.26 | I3: 7.46 | J3: 7.62 | K3: 7.76 | L3: 7.87 | M3: 7.97 | N3: 8.05 | O3: 8.12 | P3: 8.18 | Q3: 8.23 | R3: 8.28 | S3: 8.32 | T3: 8.35 | U3: 8.38 | V3: 8.41 | W3: 8.44
A4: 40275 | B4: 2.92 | C4: 4.22 | D4: 5.08 | E4: 6.07 | F4: 6.61 | G4: 6.97 | H4: 7.23 | I4: 7.43 | J4: 7.6 | K4: 7.74 | L4: 7.85 | M4: 7.95 | N4: 8.03 | O4: 8.1 | P4: 8.16 | Q4: 8.21 | R4: 8.26 | S4: 8.3 | T4: 8.33 | U4: 8.37 | V4: 8.39 | W4: 8.42
A5: 40276 | B5: 2.74 | C5: 4.44 | D5: 5.14 | E5: 5.88 | F5: 6.43 | G5: 6.87 | H5: 7.2 | I5: 7.45 | J5: 7.65 | K5: 7.79 | L5: 7.91 | M5: 8.01 | N5: 8.09 | O5: 8.15 | P5: 8.21 | Q5: 8.25 | R5: 8.29 | S5: 8.33 | T5: 8.36 | U5: 8.39 | V5: 8.41 | W5: 8.44
A6: 40277 | B6: 2.33 | C6: 4.43 | D6: 5.31 | E6: 6.15 | F6: 6.68 | G6: 7.07 | H6: 7.37 | I6: 7.58 | J6: 7.75 | K6: 7.88 | L6: 7.98 | M6: 8.06 | N6: 8.13 | O6: 8.18 | P6: 8.23 | Q6: 8.27 | R6: 8.3 | S6: 8.34 | T6: 8.36 | U6: 8.39 | V6: 8.41 | W6: 8.43
A7: 40280 | B7: 2.52 | C7: 4.17 | D7: 5.24 | E7: 6.41 | F7: 6.99 | G7: 7.33 | H7: 7.56 | I7: 7.73 | J7: 7.87 | K7: 7.97 | L7: 8.06 | M7: 8.13 | N7: 8.19 | O7: 8.24 | P7: 8.28 | Q7: 8.32 | R7: 8.35 | S7: 8.38 | T7: 8.41 | U7: 8.43 | V7: 8.45 | W7: 8.47
A8: 40281 | B8: 3 | C8: 4.24 | D8: 5.12 | E8: 6.23 | F8: 6.86 | G8: 7.25 | H8: 7.51 | I8: 7.7 | J8: 7.84 | K8: 7.94 | L8: 8.03 | M8: 8.09 | N8: 8.15 | O8: 8.2 | P8: 8.23 | Q8: 8.27 | R8: 8.3 | S8: 8.32 | T8: 8.34 | U8: 8.36 | V8: 8.38 | W8: 8.4
A9: 40283 | B9: 3.25 | C9: 4.42 | D9: 5.2 | E9: 6.14 | F9: 6.69 | G9: 7.08 | H9: 7.38 | I9: 7.61 | J9: 7.81 | K9: 7.96 | L9: 8.08 | M9: 8.18 | N9: 8.26 | O9: 8.32 | P9: 8.36 | Q9: 8.4 | R9: 8.42 | S9: 8.44 | T9: 8.46 | U9: 8.47 | V9: 8.47 | W9: 8.47
A10: 40284 | B10: 3.13 | C10: 4.47 | D10: 5.34 | E10: 6.34 | F10: 6.88 | G10: 7.24 | H10: 7.49 | I10: 7.68 | J10: 7.82 | K10: 7.94 | L10: 8.03 | M10: 8.1 | N10: 8.16 | O10: 8.21 | P10: 8.26 | Q10: 8.29 | R10: 8.33 | S10: 8.35 | T10: 8.38 | U10: 8.4 | V10: 8.42 | W10: 8.44
A11: 40287 | B11: 3.2 | C11: 4.52 | D11: 5.32 | E11: 6.26 | F11: 6.83 | G11: 7.23 | H11: 7.51 | I11: 7.71 | J11: 7.86 | K11: 7.98 | L11: 8.08 | M11: 8.15 | N11: 8.21 | O11: 8.26 | P11: 8.31 | Q11: 8.34 | R11: 8.37 | S11: 8.4 | T11: 8.43 | U11: 8.45 | V11: 8.47 | W11: 8.49
A12: 40288 | B12: 3.44 | C12: 4.46 | D12: 5.17 | E12: 6.1 | F12: 6.71 | G12: 7.13 | H12: 7.43 | I12: 7.65 | J12: 7.82 | K12: 7.94 | L12: 8.04 | M12: 8.12 | N12: 8.19 | O12: 8.24 | P12: 8.29 | Q12: 8.33 | R12: 8.36 | S12: 8.39 | T12: 8.42 | U12: 8.44 | V12: 8.46 | W12: 8.48
A13: 40289 | B13: 3.21 | C13: 4.42 | D13: 5.12 | E13: 5.98 | F13: 6.58 | G13: 7.01 | H13: 7.33 | I13: 7.57 | J13: 7.75 | K13: 7.89 | L13: 8 | M13: 8.09 | N13: 8.16 | O13: 8.22 | P13: 8.27 | Q13: 8.32 | R13: 8.35 | S13: 8.39 | T13: 8.42 | U13: 8.44 | V13: 8.47 | W13: 8.49
... A3882: 46142 | B3882: 5.14 | C3882: 5.36 | D3882: 5.57 | E3882: 5.92 | F3882: 6.2 | G3882: 6.44 | H3882: 6.63 | I3882: 6.79 | J3882: 6.93 | K3882: 7.04 | L3882: 7.14 | M3882: 7.22 | N3882: 7.29 | O3882: 7.36 | P3882: 7.41 | Q3882: 7.46 | R3882: 7.5 | S3882: 7.54 | T3882: 7.58 | U3882: 7.61 | V3882: 7.64 | W3882: 7.67

Sheet Monthly
A1: Date | B1: 3m | C1: 6m | D1: 12m | E1: 24m | F1: 36m | G1: 48m | H1: 60m | I1: 72m | J1: 84m | K1: 96m | L1: 108m | M1: 120m | N1: 132m | O1: 144m | P1: 156m | Q1: 168m | R1: 180m | S1: 192m | T1: 204m | U1: 216m | V1: 228m | W1: 240m
A2: 40269 | B2: {=AVERAGE( _xlfn._xlws.FILTER(Daily!B$2:B$10000, (Daily!$A$2:$A$10000>=EOMONTH($A2,-1)+1)*(Daily!$A$2:$A$10000<=EOMONTH($A2,0)) ) )} -> 3.0415789 | C2: {=AVERAGE( _xlfn._xlws.FILTER(Daily!C$2:C$10000, (Daily!$A$2:$A$10000>=EOMONTH($A2,-1)+1)*(Daily!$A$2:$A$10000<=EOMONTH($A2,0)) ) )} -> 4.3342105 | D2: {=AVERAGE( _xlfn._xlws.FILTER(Daily!D$2:D$10000, (Daily!$A$2:$A$10000>=EOMONTH($A2,-1)+1)*(Daily!$A$2:$A$10000<=EOMONTH($A2,0)) ) )} -> 5.1484211 | E2: {=AVERAGE( _xlfn._xlws.FILTER(Daily!E$2:E$10000, (Daily!$A$2:$A$10000>=EOMONTH($A2,-1)+1)*(Daily!$A$2:$A$10000<=EOMONTH($A2,0)) ) )} -> 6.1205263 | F2: {=AVERAGE( _xlfn._xlws.FILTER(Daily!F$2:F$10000, (Daily!$A$2:$A$10000>=EOMONTH($A2,-1)+1)*(Daily!$A$2:$A$10000<=EOMONTH($A2,0)) ) )} -> 6.7036842 | G2: {=AVERAGE( _xlfn._xlws.FILTER(Daily!G$2:G$10000, (Daily!$A$2:$A$10000>=EOMONTH($A2,-1)+1)*(Daily!$A$2:$A$10000<=EOMONTH($A2,0)) ) )} -> 7.1005263 | H2: {=AVERAGE( _xlfn._xlws.FILTER(Daily!H$2:H$10000, (Daily!$A$2:$A$10000>=EOMONTH($A2,-1)+1)*(Daily!$A$2:$A$10000<=EOMONTH($A2,0)) ) )} -> 7.3889474 | I2: {=AVERAGE( _xlfn._xlws.FILTER(Daily!I$2:I$10000, (Daily!$A$2:$A$10000>=EOMONTH($A2,-1)+1)*(Daily!$A$2:$A$10000<=EOMONTH($A2,0)) ) )} -> 7.6057895 | ... W2: {=AVERAGE( _xlfn._xlws.FILTER(Daily!W$2:W$10000, (Daily!$A$2:$A$10000>=EOMONTH($A2,-1)+1)*(Daily!$A$2:$A$10000<=EOMONTH($A2,0)) ) )} -> 8.4547368
A3: 40299 | B3: {=AVERAGE( _xlfn._xlws.FILTER(Daily!B$2:B$10000, (Daily!$A$2:$A$10000>=EOMONTH($A3,-1)+1)*(Daily!$A$2:$A$10000<=EOMONTH($A3,0)) ) )} -> 3.671 | C3: {=AVERAGE( _xlfn._xlws.FILTER(Daily!C$2:C$10000, (Daily!$A$2:$A$10000>=EOMONTH($A3,-1)+1)*(Daily!$A$2:$A$10000<=EOMONTH($A3,0)) ) )} -> 4.4415 | D3: {=AVERAGE( _xlfn._xlws.FILTER(Daily!D$2:D$10000, (Daily!$A$2:$A$10000>=EOMONTH($A3,-1)+1)*(Daily!$A$2:$A$10000<=EOMONTH($A3,0)) ) )} -> 5.042 | E3: {=AVERAGE( _xlfn._xlws.FILTER(Daily!E$2:E$10000, (Daily!$A$2:$A$10000>=EOMONTH($A3,-1)+1)*(Daily!$A$2:$A$10000<=EOMONTH($A3,0)) ) )} -> 5.9035 | F3: {=AVERAGE( _xlfn._xlws.FILTER(Daily!F$2:F$10000, (Daily!$A$2:$A$10000>=EOMONTH($A3,-1)+1)*(Daily!$A$2:$A$10000<=EOMONTH($A3,0)) ) )} -> 6.4845 | G3: {=AVERAGE( _xlfn._xlws.FILTER(Daily!G$2:G$10000, (Daily!$A$2:$A$10000>=EOMONTH($A3,-1)+1)*(Daily!$A$2:$A$10000<=EOMONTH($A3,0)) ) )} -> 6.896 | H3: {=AVERAGE( _xlfn._xlws.FILTER(Daily!H$2:H$10000, (Daily!$A$2:$A$10000>=EOMONTH($A3,-1)+1)*(Daily!$A$2:$A$10000<=EOMONTH($A3,0)) ) )} -> 7.196 | I3: {=AVERAGE( _xlfn._xlws.FILTER(Daily!I$2:I$10000, (Daily!$A$2:$A$10000>=EOMONTH($A3,-1)+1)*(Daily!$A$2:$A$10000<=EOMONTH($A3,0)) ) )} -> 7.419 | ... W3: {=AVERAGE( _xlfn._xlws.FILTER(Daily!W$2:W$10000, (Daily!$A$2:$A$10000>=EOMONTH($A3,-1)+1)*(Daily!$A$2:$A$10000<=EOMONTH($A3,0)) ) )} -> 8.218
A4: 40330 | B4: {=AVERAGE( _xlfn._xlws.FILTER(Daily!B$2:B$10000, (Daily!$A$2:$A$10000>=EOMONTH($A4,-1)+1)*(Daily!$A$2:$A$10000<=EOMONTH($A4,0)) ) )} -> 4.9818182 | C4: {=AVERAGE( _xlfn._xlws.FILTER(Daily!C$2:C$10000, (Daily!$A$2:$A$10000>=EOMONTH($A4,-1)+1)*(Daily!$A$2:$A$10000<=EOMONTH($A4,0)) ) )} -> 5.1231818 | D4: {=AVERAGE( _xlfn._xlws.FILTER(Daily!D$2:D$10000, (Daily!$A$2:$A$10000>=EOMONTH($A4,-1)+1)*(Daily!$A$2:$A$10000<=EOMONTH($A4,0)) ) )} -> 5.4118182 | E4: {=AVERAGE( _xlfn._xlws.FILTER(Daily!E$2:E$10000, (Daily!$A$2:$A$10000>=EOMONTH($A4,-1)+1)*(Daily!$A$2:$A$10000<=EOMONTH($A4,0)) ) )} -> 6.0531818 | F4: {=AVERAGE( _xlfn._xlws.FILTER(Daily!F$2:F$10000, (Daily!$A$2:$A$10000>=EOMONTH($A4,-1)+1)*(Daily!$A$2:$A$10000<=EOMONTH($A4,0)) ) )} -> 6.5872727 | G4: {=AVERAGE( _xlfn._xlws.FILTER(Daily!G$2:G$10000, (Daily!$A$2:$A$10000>=EOMONTH($A4,-1)+1)*(Daily!$A$2:$A$10000<=EOMONTH($A4,0)) ) )} -> 6.9822727 | H4: {=AVERAGE( _xlfn._xlws.FILTER(Daily!H$2:H$10000, (Daily!$A$2:$A$10000>=EOMONTH($A4,-1)+1)*(Daily!$A$2:$A$10000<=EOMONTH($A4,0)) ) )} -> 7.2695455 | I4: {=AVERAGE( _xlfn._xlws.FILTER(Daily!I$2:I$10000, (Daily!$A$2:$A$10000>=EOMONTH($A4,-1)+1)*(Daily!$A$2:$A$10000<=EOMONTH($A4,0)) ) )} -> 7.4809091 | ... W4: {=AVERAGE( _xlfn._xlws.FILTER(Daily!W$2:W$10000, (Daily!$A$2:$A$10000>=EOMONTH($A4,-1)+1)*(Daily!$A$2:$A$10000<=EOMONTH($A4,0)) ) )} -> 8.2518182
A5: 40360 | B5: {=AVERAGE( _xlfn._xlws.FILTER(Daily!B$2:B$10000, (Daily!$A$2:$A$10000>=EOMONTH($A5,-1)+1)*(Daily!$A$2:$A$10000<=EOMONTH($A5,0)) ) )} -> 4.9663636 | C5: {=AVERAGE( _xlfn._xlws.FILTER(Daily!C$2:C$10000, (Daily!$A$2:$A$10000>=EOMONTH($A5,-1)+1)*(Daily!$A$2:$A$10000<=EOMONTH($A5,0)) ) )} -> 5.4604545 | D5: {=AVERAGE( _xlfn._xlws.FILTER(Daily!D$2:D$10000, (Daily!$A$2:$A$10000>=EOMONTH($A5,-1)+1)*(Daily!$A$2:$A$10000<=EOMONTH($A5,0)) ) )} -> 5.825 | E5: {=AVERAGE( _xlfn._xlws.FILTER(Daily!E$2:E$10000, (Daily!$A$2:$A$10000>=EOMONTH($A5,-1)+1)*(Daily!$A$2:$A$10000<=EOMONTH($A5,0)) ) )} -> 6.3781818 | F5: {=AVERAGE( _xlfn._xlws.FILTER(Daily!F$2:F$10000, (Daily!$A$2:$A$10000>=EOMONTH($A5,-1)+1)*(Daily!$A$2:$A$10000<=EOMONTH($A5,0)) ) )} -> 6.79 | G5: {=AVERAGE( _xlfn._xlws.FILTER(Daily!G$2:G$10000, (Daily!$A$2:$A$10000>=EOMONTH($A5,-1)+1)*(Daily!$A$2:$A$10000<=EOMONTH($A5,0)) ) )} -> 7.1022727 | H5: {=AVERAGE( _xlfn._xlws.FILTER(Daily!H$2:H$10000, (Daily!$A$2:$A$10000>=EOMONTH($A5,-1)+1)*(Daily!$A$2:$A$10000<=EOMONTH($A5,0)) ) )} -> 7.3390909 | I5: {=AVERAGE( _xlfn._xlws.FILTER(Daily!I$2:I$10000, (Daily!$A$2:$A$10000>=EOMONTH($A5,-1)+1)*(Daily!$A$2:$A$10000<=EOMONTH($A5,0)) ) )} -> 7.5222727 | ... W5: {=AVERAGE( _xlfn._xlws.FILTER(Daily!W$2:W$10000, (Daily!$A$2:$A$10000>=EOMONTH($A5,-1)+1)*(Daily!$A$2:$A$10000<=EOMONTH($A5,0)) ) )} -> 8.3059091
A6: 40391 | B6: {=AVERAGE( _xlfn._xlws.FILTER(Daily!B$2:B$10000, (Daily!$A$2:$A$10000>=EOMONTH($A6,-1)+1)*(Daily!$A$2:$A$10000<=EOMONTH($A6,0)) ) )} -> 5.3342857 | C6: {=AVERAGE( _xlfn._xlws.FILTER(Daily!C$2:C$10000, (Daily!$A$2:$A$10000>=EOMONTH($A6,-1)+1)*(Daily!$A$2:$A$10000<=EOMONTH($A6,0)) ) )} -> 6.0361905 | D6: {=AVERAGE( _xlfn._xlws.FILTER(Daily!D$2:D$10000, (Daily!$A$2:$A$10000>=EOMONTH($A6,-1)+1)*(Daily!$A$2:$A$10000<=EOMONTH($A6,0)) ) )} -> 6.4390476 | E6: {=AVERAGE( _xlfn._xlws.FILTER(Daily!E$2:E$10000, (Daily!$A$2:$A$10000>=EOMONTH($A6,-1)+1)*(Daily!$A$2:$A$10000<=EOMONTH($A6,0)) ) )} -> 6.9357143 | F6: {=AVERAGE( _xlfn._xlws.FILTER(Daily!F$2:F$10000, (Daily!$A$2:$A$10000>=EOMONTH($A6,-1)+1)*(Daily!$A$2:$A$10000<=EOMONTH($A6,0)) ) )} -> 7.2666667 | G6: {=AVERAGE( _xlfn._xlws.FILTER(Daily!G$2:G$10000, (Daily!$A$2:$A$10000>=EOMONTH($A6,-1)+1)*(Daily!$A$2:$A$10000<=EOMONTH($A6,0)) ) )} -> 7.5071429 | H6: {=AVERAGE( _xlfn._xlws.FILTER(Daily!H$2:H$10000, (Daily!$A$2:$A$10000>=EOMONTH($A6,-1)+1)*(Daily!$A$2:$A$10000<=EOMONTH($A6,0)) ) )} -> 7.6847619 | I6: {=AVERAGE( _xlfn._xlws.FILTER(Daily!I$2:I$10000, (Daily!$A$2:$A$10000>=EOMONTH($A6,-1)+1)*(Daily!$A$2:$A$10000<=EOMONTH($A6,0)) ) )} -> 7.8180952 | ... W6: {=AVERAGE( _xlfn._xlws.FILTER(Daily!W$2:W$10000, (Daily!$A$2:$A$10000>=EOMONTH($A6,-1)+1)*(Daily!$A$2:$A$10000<=EOMONTH($A6,0)) ) )} -> 8.3352381
A7: 40422 | B7: {=AVERAGE( _xlfn._xlws.FILTER(Daily!B$2:B$10000, (Daily!$A$2:$A$10000>=EOMONTH($A7,-1)+1)*(Daily!$A$2:$A$10000<=EOMONTH($A7,0)) ) )} -> 5.6025 | C7: {=AVERAGE( _xlfn._xlws.FILTER(Daily!C$2:C$10000, (Daily!$A$2:$A$10000>=EOMONTH($A7,-1)+1)*(Daily!$A$2:$A$10000<=EOMONTH($A7,0)) ) )} -> 6.088 | D7: {=AVERAGE( _xlfn._xlws.FILTER(Daily!D$2:D$10000, (Daily!$A$2:$A$10000>=EOMONTH($A7,-1)+1)*(Daily!$A$2:$A$10000<=EOMONTH($A7,0)) ) )} -> 6.464 | E7: {=AVERAGE( _xlfn._xlws.FILTER(Daily!E$2:E$10000, (Daily!$A$2:$A$10000>=EOMONTH($A7,-1)+1)*(Daily!$A$2:$A$10000<=EOMONTH($A7,0)) ) )} -> 6.99 | F7: {=AVERAGE( _xlfn._xlws.FILTER(Daily!F$2:F$10000, (Daily!$A$2:$A$10000>=EOMONTH($A7,-1)+1)*(Daily!$A$2:$A$10000<=EOMONTH($A7,0)) ) )} -> 7.335 | G7: {=AVERAGE( _xlfn._xlws.FILTER(Daily!G$2:G$10000, (Daily!$A$2:$A$10000>=EOMONTH($A7,-1)+1)*(Daily!$A$2:$A$10000<=EOMONTH($A7,0)) ) )} -> 7.57 | H7: {=AVERAGE( _xlfn._xlws.FILTER(Daily!H$2:H$10000, (Daily!$A$2:$A$10000>=EOMONTH($A7,-1)+1)*(Daily!$A$2:$A$10000<=EOMONTH($A7,0)) ) )} -> 7.7355 | I7: {=AVERAGE( _xlfn._xlws.FILTER(Daily!I$2:I$10000, (Daily!$A$2:$A$10000>=EOMONTH($A7,-1)+1)*(Daily!$A$2:$A$10000<=EOMONTH($A7,0)) ) )} -> 7.855 | ... W7: {=AVERAGE( _xlfn._xlws.FILTER(Daily!W$2:W$10000, (Daily!$A$2:$A$10000>=EOMONTH($A7,-1)+1)*(Daily!$A$2:$A$10000<=EOMONTH($A7,0)) ) )} -> 8.3155
A8: 40452 | B8: {=AVERAGE( _xlfn._xlws.FILTER(Daily!B$2:B$10000, (Daily!$A$2:$A$10000>=EOMONTH($A8,-1)+1)*(Daily!$A$2:$A$10000<=EOMONTH($A8,0)) ) )} -> 6.0533333 | C8: {=AVERAGE( _xlfn._xlws.FILTER(Daily!C$2:C$10000, (Daily!$A$2:$A$10000>=EOMONTH($A8,-1)+1)*(Daily!$A$2:$A$10000<=EOMONTH($A8,0)) ) )} -> 6.4185714 | D8: {=AVERAGE( _xlfn._xlws.FILTER(Daily!D$2:D$10000, (Daily!$A$2:$A$10000>=EOMONTH($A8,-1)+1)*(Daily!$A$2:$A$10000<=EOMONTH($A8,0)) ) )} -> 6.6866667 | E8: {=AVERAGE( _xlfn._xlws.FILTER(Daily!E$2:E$10000, (Daily!$A$2:$A$10000>=EOMONTH($A8,-1)+1)*(Daily!$A$2:$A$10000<=EOMONTH($A8,0)) ) )} -> 7.0914286 | F8: {=AVERAGE( _xlfn._xlws.FILTER(Daily!F$2:F$10000, (Daily!$A$2:$A$10000>=EOMONTH($A8,-1)+1)*(Daily!$A$2:$A$10000<=EOMONTH($A8,0)) ) )} -> 7.3928571 | G8: {=AVERAGE( _xlfn._xlws.FILTER(Daily!G$2:G$10000, (Daily!$A$2:$A$10000>=EOMONTH($A8,-1)+1)*(Daily!$A$2:$A$10000<=EOMONTH($A8,0)) ) )} -> 7.6114286 | H8: {=AVERAGE( _xlfn._xlws.FILTER(Daily!H$2:H$10000, (Daily!$A$2:$A$10000>=EOMONTH($A8,-1)+1)*(Daily!$A$2:$A$10000<=EOMONTH($A8,0)) ) )} -> 7.7742857 | I8: {=AVERAGE( _xlfn._xlws.FILTER(Daily!I$2:I$10000, (Daily!$A$2:$A$10000>=EOMONTH($A8,-1)+1)*(Daily!$A$2:$A$10000<=EOMONTH($A8,0)) ) )} -> 7.8947619 | ... W8: {=AVERAGE( _xlfn._xlws.FILTER(Daily!W$2:W$10000, (Daily!$A$2:$A$10000>=EOMONTH($A8,-1)+1)*(Daily!$A$2:$A$10000<=EOMONTH($A8,0)) ) )} -> 8.3514286
A9: 40483 | B9: {=AVERAGE( _xlfn._xlws.FILTER(Daily!B$2:B$10000, (Daily!$A$2:$A$10000>=EOMONTH($A9,-1)+1)*(Daily!$A$2:$A$10000<=EOMONTH($A9,0)) ) )} -> 6.187 | C9: {=AVERAGE( _xlfn._xlws.FILTER(Daily!C$2:C$10000, (Daily!$A$2:$A$10000>=EOMONTH($A9,-1)+1)*(Daily!$A$2:$A$10000<=EOMONTH($A9,0)) ) )} -> 6.737 | D9: {=AVERAGE( _xlfn._xlws.FILTER(Daily!D$2:D$10000, (Daily!$A$2:$A$10000>=EOMONTH($A9,-1)+1)*(Daily!$A$2:$A$10000<=EOMONTH($A9,0)) ) )} -> 7.0045 | E9: {=AVERAGE( _xlfn._xlws.FILTER(Daily!E$2:E$10000, (Daily!$A$2:$A$10000>=EOMONTH($A9,-1)+1)*(Daily!$A$2:$A$10000<=EOMONTH($A9,0)) ) )} -> 7.2625 | F9: {=AVERAGE( _xlfn._xlws.FILTER(Daily!F$2:F$10000, (Daily!$A$2:$A$10000>=EOMONTH($A9,-1)+1)*(Daily!$A$2:$A$10000<=EOMONTH($A9,0)) ) )} -> 7.43 | G9: {=AVERAGE( _xlfn._xlws.FILTER(Daily!G$2:G$10000, (Daily!$A$2:$A$10000>=EOMONTH($A9,-1)+1)*(Daily!$A$2:$A$10000<=EOMONTH($A9,0)) ) )} -> 7.575 | H9: {=AVERAGE( _xlfn._xlws.FILTER(Daily!H$2:H$10000, (Daily!$A$2:$A$10000>=EOMONTH($A9,-1)+1)*(Daily!$A$2:$A$10000<=EOMONTH($A9,0)) ) )} -> 7.701 | I9: {=AVERAGE( _xlfn._xlws.FILTER(Daily!I$2:I$10000, (Daily!$A$2:$A$10000>=EOMONTH($A9,-1)+1)*(Daily!$A$2:$A$10000<=EOMONTH($A9,0)) ) )} -> 7.8115 | ... W9: {=AVERAGE( _xlfn._xlws.FILTER(Daily!W$2:W$10000, (Daily!$A$2:$A$10000>=EOMONTH($A9,-1)+1)*(Daily!$A$2:$A$10000<=EOMONTH($A9,0)) ) )} -> 8.362
A10: 40513 | B10: {=AVERAGE( _xlfn._xlws.FILTER(Daily!B$2:B$10000, (Daily!$A$2:$A$10000>=EOMONTH($A10,-1)+1)*(Daily!$A$2:$A$10000<=EOMONTH($A10,0)) ) )} -> 6.5363636 | C10: {=AVERAGE( _xlfn._xlws.FILTER(Daily!C$2:C$10000, (Daily!$A$2:$A$10000>=EOMONTH($A10,-1)+1)*(Daily!$A$2:$A$10000<=EOMONTH($A10,0)) ) )} -> 7.025 | D10: {=AVERAGE( _xlfn._xlws.FILTER(Daily!D$2:D$10000, (Daily!$A$2:$A$10000>=EOMONTH($A10,-1)+1)*(Daily!$A$2:$A$10000<=EOMONTH($A10,0)) ) )} -> 7.2827273 | E10: {=AVERAGE( _xlfn._xlws.FILTER(Daily!E$2:E$10000, (Daily!$A$2:$A$10000>=EOMONTH($A10,-1)+1)*(Daily!$A$2:$A$10000<=EOMONTH($A10,0)) ) )} -> 7.4918182 | F10: {=AVERAGE( _xlfn._xlws.FILTER(Daily!F$2:F$10000, (Daily!$A$2:$A$10000>=EOMONTH($A10,-1)+1)*(Daily!$A$2:$A$10000<=EOMONTH($A10,0)) ) )} -> 7.5772727 | G10: {=AVERAGE( _xlfn._xlws.FILTER(Daily!G$2:G$10000, (Daily!$A$2:$A$10000>=EOMONTH($A10,-1)+1)*(Daily!$A$2:$A$10000<=EOMONTH($A10,0)) ) )} -> 7.6463636 | H10: {=AVERAGE( _xlfn._xlws.FILTER(Daily!H$2:H$10000, (Daily!$A$2:$A$10000>=EOMONTH($A10,-1)+1)*(Daily!$A$2:$A$10000<=EOMONTH($A10,0)) ) )} -> 7.7181818 | I10: {=AVERAGE( _xlfn._xlws.FILTER(Daily!I$2:I$10000, (Daily!$A$2:$A$10000>=EOMONTH($A10,-1)+1)*(Daily!$A$2:$A$10000<=EOMONTH($A10,0)) ) )} -> 7.795 | ... W10: {=AVERAGE( _xlfn._xlws.FILTER(Daily!W$2:W$10000, (Daily!$A$2:$A$10000>=EOMONTH($A10,-1)+1)*(Daily!$A$2:$A$10000<=EOMONTH($A10,0)) ) )} -> 8.3954545
A11: 40544 | B11: {=AVERAGE( _xlfn._xlws.FILTER(Daily!B$2:B$10000, (Daily!$A$2:$A$10000>=EOMONTH($A11,-1)+1)*(Daily!$A$2:$A$10000<=EOMONTH($A11,0)) ) )} -> 6.145 | C11: {=AVERAGE( _xlfn._xlws.FILTER(Daily!C$2:C$10000, (Daily!$A$2:$A$10000>=EOMONTH($A11,-1)+1)*(Daily!$A$2:$A$10000<=EOMONTH($A11,0)) ) )} -> 7.1385 | D11: {=AVERAGE( _xlfn._xlws.FILTER(Daily!D$2:D$10000, (Daily!$A$2:$A$10000>=EOMONTH($A11,-1)+1)*(Daily!$A$2:$A$10000<=EOMONTH($A11,0)) ) )} -> 7.418 | E11: {=AVERAGE( _xlfn._xlws.FILTER(Daily!E$2:E$10000, (Daily!$A$2:$A$10000>=EOMONTH($A11,-1)+1)*(Daily!$A$2:$A$10000<=EOMONTH($A11,0)) ) )} -> 7.5725 | F11: {=AVERAGE( _xlfn._xlws.FILTER(Daily!F$2:F$10000, (Daily!$A$2:$A$10000>=EOMONTH($A11,-1)+1)*(Daily!$A$2:$A$10000<=EOMONTH($A11,0)) ) )} -> 7.633 | G11: {=AVERAGE( _xlfn._xlws.FILTER(Daily!G$2:G$10000, (Daily!$A$2:$A$10000>=EOMONTH($A11,-1)+1)*(Daily!$A$2:$A$10000<=EOMONTH($A11,0)) ) )} -> 7.703 | H11: {=AVERAGE( _xlfn._xlws.FILTER(Daily!H$2:H$10000, (Daily!$A$2:$A$10000>=EOMONTH($A11,-1)+1)*(Daily!$A$2:$A$10000<=EOMONTH($A11,0)) ) )} -> 7.7855 | I11: {=AVERAGE( _xlfn._xlws.FILTER(Daily!I$2:I$10000, (Daily!$A$2:$A$10000>=EOMONTH($A11,-1)+1)*(Daily!$A$2:$A$10000<=EOMONTH($A11,0)) ) )} -> 7.8705 | ... W11: {=AVERAGE( _xlfn._xlws.FILTER(Daily!W$2:W$10000, (Daily!$A$2:$A$10000>=EOMONTH($A11,-1)+1)*(Daily!$A$2:$A$10000<=EOMONTH($A11,0)) ) )} -> 8.4675
A12: 40575 | B12: {=AVERAGE( _xlfn._xlws.FILTER(Daily!B$2:B$10000, (Daily!$A$2:$A$10000>=EOMONTH($A12,-1)+1)*(Daily!$A$2:$A$10000<=EOMONTH($A12,0)) ) )} -> 5.8494737 | C12: {=AVERAGE( _xlfn._xlws.FILTER(Daily!C$2:C$10000, (Daily!$A$2:$A$10000>=EOMONTH($A12,-1)+1)*(Daily!$A$2:$A$10000<=EOMONTH($A12,0)) ) )} -> 7.26 | D12: {=AVERAGE( _xlfn._xlws.FILTER(Daily!D$2:D$10000, (Daily!$A$2:$A$10000>=EOMONTH($A12,-1)+1)*(Daily!$A$2:$A$10000<=EOMONTH($A12,0)) ) )} -> 7.4857895 | E12: {=AVERAGE( _xlfn._xlws.FILTER(Daily!E$2:E$10000, (Daily!$A$2:$A$10000>=EOMONTH($A12,-1)+1)*(Daily!$A$2:$A$10000<=EOMONTH($A12,0)) ) )} -> 7.53 | F12: {=AVERAGE( _xlfn._xlws.FILTER(Daily!F$2:F$10000, (Daily!$A$2:$A$10000>=EOMONTH($A12,-1)+1)*(Daily!$A$2:$A$10000<=EOMONTH($A12,0)) ) )} -> 7.5857895 | G12: {=AVERAGE( _xlfn._xlws.FILTER(Daily!G$2:G$10000, (Daily!$A$2:$A$10000>=EOMONTH($A12,-1)+1)*(Daily!$A$2:$A$10000<=EOMONTH($A12,0)) ) )} -> 7.6784211 | H12: {=AVERAGE( _xlfn._xlws.FILTER(Daily!H$2:H$10000, (Daily!$A$2:$A$10000>=EOMONTH($A12,-1)+1)*(Daily!$A$2:$A$10000<=EOMONTH($A12,0)) ) )} -> 7.7831579 | I12: {=AVERAGE( _xlfn._xlws.FILTER(Daily!I$2:I$10000, (Daily!$A$2:$A$10000>=EOMONTH($A12,-1)+1)*(Daily!$A$2:$A$10000<=EOMONTH($A12,0)) ) )} -> 7.8878947 | ... W12: {=AVERAGE( _xlfn._xlws.FILTER(Daily!W$2:W$10000, (Daily!$A$2:$A$10000>=EOMONTH($A12,-1)+1)*(Daily!$A$2:$A$10000<=EOMONTH($A12,0)) ) )} -> 8.4889474
A13: 40603 | B13: {=AVERAGE( _xlfn._xlws.FILTER(Daily!B$2:B$10000, (Daily!$A$2:$A$10000>=EOMONTH($A13,-1)+1)*(Daily!$A$2:$A$10000<=EOMONTH($A13,0)) ) )} -> 5.9740909 | C13: {=AVERAGE( _xlfn._xlws.FILTER(Daily!C$2:C$10000, (Daily!$A$2:$A$10000>=EOMONTH($A13,-1)+1)*(Daily!$A$2:$A$10000<=EOMONTH($A13,0)) ) )} -> 7.3263636 | D13: {=AVERAGE( _xlfn._xlws.FILTER(Daily!D$2:D$10000, (Daily!$A$2:$A$10000>=EOMONTH($A13,-1)+1)*(Daily!$A$2:$A$10000<=EOMONTH($A13,0)) ) )} -> 7.3754545 | E13: {=AVERAGE( _xlfn._xlws.FILTER(Daily!E$2:E$10000, (Daily!$A$2:$A$10000>=EOMONTH($A13,-1)+1)*(Daily!$A$2:$A$10000<=EOMONTH($A13,0)) ) )} -> 7.3386364 | F13: {=AVERAGE( _xlfn._xlws.FILTER(Daily!F$2:F$10000, (Daily!$A$2:$A$10000>=EOMONTH($A13,-1)+1)*(Daily!$A$2:$A$10000<=EOMONTH($A13,0)) ) )} -> 7.4172727 | G13: {=AVERAGE( _xlfn._xlws.FILTER(Daily!G$2:G$10000, (Daily!$A$2:$A$10000>=EOMONTH($A13,-1)+1)*(Daily!$A$2:$A$10000<=EOMONTH($A13,0)) ) )} -> 7.5436364 | H13: {=AVERAGE( _xlfn._xlws.FILTER(Daily!H$2:H$10000, (Daily!$A$2:$A$10000>=EOMONTH($A13,-1)+1)*(Daily!$A$2:$A$10000<=EOMONTH($A13,0)) ) )} -> 7.6731818 | I13: {=AVERAGE( _xlfn._xlws.FILTER(Daily!I$2:I$10000, (Daily!$A$2:$A$10000>=EOMONTH($A13,-1)+1)*(Daily!$A$2:$A$10000<=EOMONTH($A13,0)) ) )} -> 7.7895455 | ... W13: {=AVERAGE( _xlfn._xlws.FILTER(Daily!W$2:W$10000, (Daily!$A$2:$A$10000>=EOMONTH($A13,-1)+1)*(Daily!$A$2:$A$10000<=EOMONTH($A13,0)) ) )} -> 8.3472727
... A196: 46113 | B196: {=AVERAGE( _xlfn._xlws.FILTER(Daily!B$2:B$10000, (Daily!$A$2:$A$10000>=EOMONTH($A196,-1)+1)*(Daily!$A$2:$A$10000<=EOMONTH($A196,0)) ) )} -> 5.2063158 | C196: {=AVERAGE( _xlfn._xlws.FILTER(Daily!C$2:C$10000, (Daily!$A$2:$A$10000>=EOMONTH($A196,-1)+1)*(Daily!$A$2:$A$10000<=EOMONTH($A196,0)) ) )} -> 5.3921053 | D196: {=AVERAGE( _xlfn._xlws.FILTER(Daily!D$2:D$10000, (Daily!$A$2:$A$10000>=EOMONTH($A196,-1)+1)*(Daily!$A$2:$A$10000<=EOMONTH($A196,0)) ) )} -> 5.5647368 | E196: {=AVERAGE( _xlfn._xlws.FILTER(Daily!E$2:E$10000, (Daily!$A$2:$A$10000>=EOMONTH($A196,-1)+1)*(Daily!$A$2:$A$10000<=EOMONTH($A196,0)) ) )} -> 5.8694737 | F196: {=AVERAGE( _xlfn._xlws.FILTER(Daily!F$2:F$10000, (Daily!$A$2:$A$10000>=EOMONTH($A196,-1)+1)*(Daily!$A$2:$A$10000<=EOMONTH($A196,0)) ) )} -> 6.1252632 | G196: {=AVERAGE( _xlfn._xlws.FILTER(Daily!G$2:G$10000, (Daily!$A$2:$A$10000>=EOMONTH($A196,-1)+1)*(Daily!$A$2:$A$10000<=EOMONTH($A196,0)) ) )} -> 6.3452632 | H196: {=AVERAGE( _xlfn._xlws.FILTER(Daily!H$2:H$10000, (Daily!$A$2:$A$10000>=EOMONTH($A196,-1)+1)*(Daily!$A$2:$A$10000<=EOMONTH($A196,0)) ) )} -> 6.5315789 | I196: {=AVERAGE( _xlfn._xlws.FILTER(Daily!I$2:I$10000, (Daily!$A$2:$A$10000>=EOMONTH($A196,-1)+1)*(Daily!$A$2:$A$10000<=EOMONTH($A196,0)) ) )} -> 6.6936842 | ... W196: {=AVERAGE( _xlfn._xlws.FILTER(Daily!W$2:W$10000, (Daily!$A$2:$A$10000>=EOMONTH($A196,-1)+1)*(Daily!$A$2:$A$10000<=EOMONTH($A196,0)) ) )} -> 7.6563158

Sheet Eomonth
C1: 2 | D1: 3 | E1: 4 | F1: 5 | G1: 6 | H1: 7 | I1: 8 | J1: 9 | K1: 10 | L1: 11 | M1: 12 | N1: 13 | O1: 14 | P1: 15 | Q1: 16 | R1: 17 | S1: 18 | T1: 19 | U1: 20 | V1: 21 | W1: 22 | X1: 23
A2: Date | C2: =Monthly!B1 -> 3m | D2: =Monthly!C1 -> 6m | E2: =Monthly!D1 -> 12m | F2: =Monthly!E1 -> 24m | G2: =Monthly!F1 -> 36m | H2: =Monthly!G1 -> 48m | I2: =Monthly!H1 -> 60m | J2: =Monthly!I1 -> 72m | ... X2: =Monthly!W1 -> 240m
A3: 40269 | B3: =WORKDAY(EOMONTH(A3,0)+1, -1) -> 40298 | C3: =(VLOOKUP($B3,Daily!$A$1:$W$10000,C$1,FALSE))/100 -> 0.0282 | D3: =(VLOOKUP($B3,Daily!$A$1:$W$10000,D$1,FALSE))/100 -> 0.0407 | E3: =(VLOOKUP($B3,Daily!$A$1:$W$10000,E$1,FALSE))/100 -> 0.0496 | F3: =(VLOOKUP($B3,Daily!$A$1:$W$10000,F$1,FALSE))/100 -> 0.0607 | G3: =(VLOOKUP($B3,Daily!$A$1:$W$10000,G$1,FALSE))/100 -> 0.0672 | H3: =(VLOOKUP($B3,Daily!$A$1:$W$10000,H$1,FALSE))/100 -> 0.0713 | I3: =(VLOOKUP($B3,Daily!$A$1:$W$10000,I$1,FALSE))/100 -> 0.0741 | J3: =(VLOOKUP($B3,Daily!$A$1:$W$10000,J$1,FALSE))/100 -> 0.0761 | ... X3: =(VLOOKUP($B3,Daily!$A$1:$W$10000,X$1,FALSE))/100 -> 0.0839
A4: 40299 | B4: =WORKDAY(EOMONTH(A4,0)+1, -1) -> 40329 | C4: =(VLOOKUP($B4,Daily!$A$1:$W$10000,C$1,FALSE))/100 -> 0.0483 | D4: =(VLOOKUP($B4,Daily!$A$1:$W$10000,D$1,FALSE))/100 -> 0.05 | E4: =(VLOOKUP($B4,Daily!$A$1:$W$10000,E$1,FALSE))/100 -> 0.0528 | F4: =(VLOOKUP($B4,Daily!$A$1:$W$10000,F$1,FALSE))/100 -> 0.059 | G4: =(VLOOKUP($B4,Daily!$A$1:$W$10000,G$1,FALSE))/100 -> 0.0646 | H4: =(VLOOKUP($B4,Daily!$A$1:$W$10000,H$1,FALSE))/100 -> 0.069 | I4: =(VLOOKUP($B4,Daily!$A$1:$W$10000,I$1,FALSE))/100 -> 0.0722 | J4: =(VLOOKUP($B4,Daily!$A$1:$W$10000,J$1,FALSE))/100 -> 0.0746 | ... X4: =(VLOOKUP($B4,Daily!$A$1:$W$10000,X$1,FALSE))/100 -> 0.0819
A5: 40330 | B5: =WORKDAY(EOMONTH(A5,0)+1, -1) -> 40359 | C5: =(VLOOKUP($B5,Daily!$A$1:$W$10000,C$1,FALSE))/100 -> 0.0505 | D5: =(VLOOKUP($B5,Daily!$A$1:$W$10000,D$1,FALSE))/100 -> 0.0519 | E5: =(VLOOKUP($B5,Daily!$A$1:$W$10000,E$1,FALSE))/100 -> 0.0548 | F5: =(VLOOKUP($B5,Daily!$A$1:$W$10000,F$1,FALSE))/100 -> 0.0612 | G5: =(VLOOKUP($B5,Daily!$A$1:$W$10000,G$1,FALSE))/100 -> 0.0664 | H5: =(VLOOKUP($B5,Daily!$A$1:$W$10000,H$1,FALSE))/100 -> 0.0703 | I5: =(VLOOKUP($B5,Daily!$A$1:$W$10000,I$1,FALSE))/100 -> 0.073 | J5: =(VLOOKUP($B5,Daily!$A$1:$W$10000,J$1,FALSE))/100 -> 0.075 | ... X5: =(VLOOKUP($B5,Daily!$A$1:$W$10000,X$1,FALSE))/100 -> 0.0824
A6: 40360 | B6: =WORKDAY(EOMONTH(A6,0)+1, -1) -> 40389 | C6: =(VLOOKUP($B6,Daily!$A$1:$W$10000,C$1,FALSE))/100 -> 0.052 | D6: =(VLOOKUP($B6,Daily!$A$1:$W$10000,D$1,FALSE))/100 -> 0.0569 | E6: =(VLOOKUP($B6,Daily!$A$1:$W$10000,E$1,FALSE))/100 -> 0.0609 | F6: =(VLOOKUP($B6,Daily!$A$1:$W$10000,F$1,FALSE))/100 -> 0.0668 | G6: =(VLOOKUP($B6,Daily!$A$1:$W$10000,G$1,FALSE))/100 -> 0.0709 | H6: =(VLOOKUP($B6,Daily!$A$1:$W$10000,H$1,FALSE))/100 -> 0.0737 | I6: =(VLOOKUP($B6,Daily!$A$1:$W$10000,I$1,FALSE))/100 -> 0.0757 | J6: =(VLOOKUP($B6,Daily!$A$1:$W$10000,J$1,FALSE))/100 -> 0.0772 | ... X6: =(VLOOKUP($B6,Daily!$A$1:$W$10000,X$1,FALSE))/100 -> 0.0831
A7: 40391 | B7: =WORKDAY(EOMONTH(A7,0)+1, -1) -> 40421 | C7: =(VLOOKUP($B7,Daily!$A$1:$W$10000,C$1,FALSE))/100 -> 0.0576 | D7: =(VLOOKUP($B7,Daily!$A$1:$W$10000,D$1,FALSE))/100 -> 0.0609 | E7: =(VLOOKUP($B7,Daily!$A$1:$W$10000,E$1,FALSE))/100 -> 0.064 | F7: =(VLOOKUP($B7,Daily!$A$1:$W$10000,F$1,FALSE))/100 -> 0.0691 | G7: =(VLOOKUP($B7,Daily!$A$1:$W$10000,G$1,FALSE))/100 -> 0.0728 | H7: =(VLOOKUP($B7,Daily!$A$1:$W$10000,H$1,FALSE))/100 -> 0.0753 | I7: =(VLOOKUP($B7,Daily!$A$1:$W$10000,I$1,FALSE))/100 -> 0.0771 | J7: =(VLOOKUP($B7,Daily!$A$1:$W$10000,J$1,FALSE))/100 -> 0.0784 | ... X7: =(VLOOKUP($B7,Daily!$A$1:$W$10000,X$1,FALSE))/100 -> 0.0831
A8: 40422 | B8: =WORKDAY(EOMONTH(A8,0)+1, -1)-1 -> 40450 | C8: =(VLOOKUP($B8,Daily!$A$1:$W$10000,C$1,FALSE))/100 -> 0.0559 | D8: =(VLOOKUP($B8,Daily!$A$1:$W$10000,D$1,FALSE))/100 -> 0.0628 | E8: =(VLOOKUP($B8,Daily!$A$1:$W$10000,E$1,FALSE))/100 -> 0.0661 | F8: =(VLOOKUP($B8,Daily!$A$1:$W$10000,F$1,FALSE))/100 -> 0.0699 | G8: =(VLOOKUP($B8,Daily!$A$1:$W$10000,G$1,FALSE))/100 -> 0.0727 | H8: =(VLOOKUP($B8,Daily!$A$1:$W$10000,H$1,FALSE))/100 -> 0.0748 | I8: =(VLOOKUP($B8,Daily!$A$1:$W$10000,I$1,FALSE))/100 -> 0.0765 | J8: =(VLOOKUP($B8,Daily!$A$1:$W$10000,J$1,FALSE))/100 -> 0.0777 | ... X8: =(VLOOKUP($B8,Daily!$A$1:$W$10000,X$1,FALSE))/100 -> 0.0825
A9: 40452 | B9: =WORKDAY(EOMONTH(A9,0)+1, -1) -> 40480 | C9: =(VLOOKUP($B9,Daily!$A$1:$W$10000,C$1,FALSE))/100 -> 0.0631 | D9: =(VLOOKUP($B9,Daily!$A$1:$W$10000,D$1,FALSE))/100 -> 0.066 | E9: =(VLOOKUP($B9,Daily!$A$1:$W$10000,E$1,FALSE))/100 -> 0.0685 | F9: =(VLOOKUP($B9,Daily!$A$1:$W$10000,F$1,FALSE))/100 -> 0.0722 | G9: =(VLOOKUP($B9,Daily!$A$1:$W$10000,G$1,FALSE))/100 -> 0.0749 | H9: =(VLOOKUP($B9,Daily!$A$1:$W$10000,H$1,FALSE))/100 -> 0.0768 | I9: =(VLOOKUP($B9,Daily!$A$1:$W$10000,I$1,FALSE))/100 -> 0.0782 | J9: =(VLOOKUP($B9,Daily!$A$1:$W$10000,J$1,FALSE))/100 -> 0.0793 | ... X9: =(VLOOKUP($B9,Daily!$A$1:$W$10000,X$1,FALSE))/100 -> 0.0838
A10: 40483 | B10: =WORKDAY(EOMONTH(A10,0)+1, -1) -> 40512 | C10: =(VLOOKUP($B10,Daily!$A$1:$W$10000,C$1,FALSE))/100 -> 0.0649 | D10: =(VLOOKUP($B10,Daily!$A$1:$W$10000,D$1,FALSE))/100 -> 0.0687 | E10: =(VLOOKUP($B10,Daily!$A$1:$W$10000,E$1,FALSE))/100 -> 0.0713 | F10: =(VLOOKUP($B10,Daily!$A$1:$W$10000,F$1,FALSE))/100 -> 0.0742 | G10: =(VLOOKUP($B10,Daily!$A$1:$W$10000,G$1,FALSE))/100 -> 0.0759 | H10: =(VLOOKUP($B10,Daily!$A$1:$W$10000,H$1,FALSE))/100 -> 0.077 | I10: =(VLOOKUP($B10,Daily!$A$1:$W$10000,I$1,FALSE))/100 -> 0.0778 | J10: =(VLOOKUP($B10,Daily!$A$1:$W$10000,J$1,FALSE))/100 -> 0.0786 | ... X10: =(VLOOKUP($B10,Daily!$A$1:$W$10000,X$1,FALSE))/100 -> 0.0837
A11: 40513 | B11: =WORKDAY(EOMONTH(A11,0)+1, -1) -> 40543 | C11: =(VLOOKUP($B11,Daily!$A$1:$W$10000,C$1,FALSE))/100 -> 0.0651 | D11: =(VLOOKUP($B11,Daily!$A$1:$W$10000,D$1,FALSE))/100 -> 0.0689 | E11: =(VLOOKUP($B11,Daily!$A$1:$W$10000,E$1,FALSE))/100 -> 0.0715 | F11: =(VLOOKUP($B11,Daily!$A$1:$W$10000,F$1,FALSE))/100 -> 0.0744 | G11: =(VLOOKUP($B11,Daily!$A$1:$W$10000,G$1,FALSE))/100 -> 0.0758 | H11: =(VLOOKUP($B11,Daily!$A$1:$W$10000,H$1,FALSE))/100 -> 0.0765 | I11: =(VLOOKUP($B11,Daily!$A$1:$W$10000,I$1,FALSE))/100 -> 0.0771 | J11: =(VLOOKUP($B11,Daily!$A$1:$W$10000,J$1,FALSE))/100 -> 0.0777 | ... X11: =(VLOOKUP($B11,Daily!$A$1:$W$10000,X$1,FALSE))/100 -> 0.0837
A12: 40544 | B12: =WORKDAY(EOMONTH(A12,0)+1, -1) -> 40574 | C12: =(VLOOKUP($B12,Daily!$A$1:$W$10000,C$1,FALSE))/100 -> 0.0603 | D12: =(VLOOKUP($B12,Daily!$A$1:$W$10000,D$1,FALSE))/100 -> 0.0733 | E12: =(VLOOKUP($B12,Daily!$A$1:$W$10000,E$1,FALSE))/100 -> 0.0752 | F12: =(VLOOKUP($B12,Daily!$A$1:$W$10000,F$1,FALSE))/100 -> 0.0754 | G12: =(VLOOKUP($B12,Daily!$A$1:$W$10000,G$1,FALSE))/100 -> 0.0759 | H12: =(VLOOKUP($B12,Daily!$A$1:$W$10000,H$1,FALSE))/100 -> 0.0768 | I12: =(VLOOKUP($B12,Daily!$A$1:$W$10000,I$1,FALSE))/100 -> 0.0779 | J12: =(VLOOKUP($B12,Daily!$A$1:$W$10000,J$1,FALSE))/100 -> 0.0789 | ... X12: =(VLOOKUP($B12,Daily!$A$1:$W$10000,X$1,FALSE))/100 -> 0.0849
A13: 40575 | B13: =WORKDAY(EOMONTH(A13,0)+1, -1) -> 40602 | C13: =(VLOOKUP($B13,Daily!$A$1:$W$10000,C$1,FALSE))/100 -> 0.0588 | D13: =(VLOOKUP($B13,Daily!$A$1:$W$10000,D$1,FALSE))/100 -> 0.0733 | E13: =(VLOOKUP($B13,Daily!$A$1:$W$10000,E$1,FALSE))/100 -> 0.0739 | F13: =(VLOOKUP($B13,Daily!$A$1:$W$10000,F$1,FALSE))/100 -> 0.0734 | G13: =(VLOOKUP($B13,Daily!$A$1:$W$10000,G$1,FALSE))/100 -> 0.0741 | H13: =(VLOOKUP($B13,Daily!$A$1:$W$10000,H$1,FALSE))/100 -> 0.0754 | I13: =(VLOOKUP($B13,Daily!$A$1:$W$10000,I$1,FALSE))/100 -> 0.0769 | J13: =(VLOOKUP($B13,Daily!$A$1:$W$10000,J$1,FALSE))/100 -> 0.0782 | ... X13: =(VLOOKUP($B13,Daily!$A$1:$W$10000,X$1,FALSE))/100 -> 0.0846
A14: 40603 | B14: =WORKDAY(EOMONTH(A14,0)+1, -1) -> 40633 | C14: =(VLOOKUP($B14,Daily!$A$1:$W$10000,C$1,FALSE))/100 -> 0.0673 | D14: =(VLOOKUP($B14,Daily!$A$1:$W$10000,D$1,FALSE))/100 -> 0.0726 | E14: =(VLOOKUP($B14,Daily!$A$1:$W$10000,E$1,FALSE))/100 -> 0.0747 | F14: =(VLOOKUP($B14,Daily!$A$1:$W$10000,F$1,FALSE))/100 -> 0.0754 | G14: =(VLOOKUP($B14,Daily!$A$1:$W$10000,G$1,FALSE))/100 -> 0.0755 | H14: =(VLOOKUP($B14,Daily!$A$1:$W$10000,H$1,FALSE))/100 -> 0.076 | I14: =(VLOOKUP($B14,Daily!$A$1:$W$10000,I$1,FALSE))/100 -> 0.0769 | J14: =(VLOOKUP($B14,Daily!$A$1:$W$10000,J$1,FALSE))/100 -> 0.0778 | ... X14: =(VLOOKUP($B14,Daily!$A$1:$W$10000,X$1,FALSE))/100 -> 0.0835
A15: 40634 | B15: =WORKDAY(EOMONTH(A15,0)+1, -1) -> 40662 | C15: =(VLOOKUP($B15,Daily!$A$1:$W$10000,C$1,FALSE))/100 -> 0.0705 | D15: =(VLOOKUP($B15,Daily!$A$1:$W$10000,D$1,FALSE))/100 -> 0.0784 | E15: =(VLOOKUP($B15,Daily!$A$1:$W$10000,E$1,FALSE))/100 -> 0.0792 | F15: =(VLOOKUP($B15,Daily!$A$1:$W$10000,F$1,FALSE))/100 -> 0.0787 | G15: =(VLOOKUP($B15,Daily!$A$1:$W$10000,G$1,FALSE))/100 -> 0.0785 | H15: =(VLOOKUP($B15,Daily!$A$1:$W$10000,H$1,FALSE))/100 -> 0.0788 | I15: =(VLOOKUP($B15,Daily!$A$1:$W$10000,I$1,FALSE))/100 -> 0.0793 | J15: =(VLOOKUP($B15,Daily!$A$1:$W$10000,J$1,FALSE))/100 -> 0.0799 | ... X15: =(VLOOKUP($B15,Daily!$A$1:$W$10000,X$1,FALSE))/100 -> 0.0845
A16: 40664 | B16: =WORKDAY(EOMONTH(A16,0)+1, -1) -> 40694 | C16: =(VLOOKUP($B16,Daily!$A$1:$W$10000,C$1,FALSE))/100 -> 0.075 | D16: =(VLOOKUP($B16,Daily!$A$1:$W$10000,D$1,FALSE))/100 -> 0.0819 | E16: =(VLOOKUP($B16,Daily!$A$1:$W$10000,E$1,FALSE))/100 -> 0.0805 | F16: =(VLOOKUP($B16,Daily!$A$1:$W$10000,F$1,FALSE))/100 -> 0.0791 | G16: =(VLOOKUP($B16,Daily!$A$1:$W$10000,G$1,FALSE))/100 -> 0.0793 | H16: =(VLOOKUP($B16,Daily!$A$1:$W$10000,H$1,FALSE))/100 -> 0.0801 | I16: =(VLOOKUP($B16,Daily!$A$1:$W$10000,I$1,FALSE))/100 -> 0.0809 | J16: =(VLOOKUP($B16,Daily!$A$1:$W$10000,J$1,FALSE))/100 -> 0.0817 | ... X16: =(VLOOKUP($B16,Daily!$A$1:$W$10000,X$1,FALSE))/100 -> 0.0856
A17: 40695 | B17: =WORKDAY(EOMONTH(A17,0)+1, -1) -> 40724 | C17: =(VLOOKUP($B17,Daily!$A$1:$W$10000,C$1,FALSE))/100 -> 0.077 | D17: =(VLOOKUP($B17,Daily!$A$1:$W$10000,D$1,FALSE))/100 -> 0.0813 | E17: =(VLOOKUP($B17,Daily!$A$1:$W$10000,E$1,FALSE))/100 -> 0.0809 | F17: =(VLOOKUP($B17,Daily!$A$1:$W$10000,F$1,FALSE))/100 -> 0.0798 | G17: =(VLOOKUP($B17,Daily!$A$1:$W$10000,G$1,FALSE))/100 -> 0.0796 | H17: =(VLOOKUP($B17,Daily!$A$1:$W$10000,H$1,FALSE))/100 -> 0.08 | I17: =(VLOOKUP($B17,Daily!$A$1:$W$10000,I$1,FALSE))/100 -> 0.0805 | J17: =(VLOOKUP($B17,Daily!$A$1:$W$10000,J$1,FALSE))/100 -> 0.0811 | ... X17: =(VLOOKUP($B17,Daily!$A$1:$W$10000,X$1,FALSE))/100 -> 0.0851
A18: 40725 | B18: =WORKDAY(EOMONTH(A18,0)+1, -1) -> 40753 | C18: =(VLOOKUP($B18,Daily!$A$1:$W$10000,C$1,FALSE))/100 -> 0.0823 | D18: =(VLOOKUP($B18,Daily!$A$1:$W$10000,D$1,FALSE))/100 -> 0.0821 | E18: =(VLOOKUP($B18,Daily!$A$1:$W$10000,E$1,FALSE))/100 -> 0.082 | F18: =(VLOOKUP($B18,Daily!$A$1:$W$10000,F$1,FALSE))/100 -> 0.0819 | G18: =(VLOOKUP($B18,Daily!$A$1:$W$10000,G$1,FALSE))/100 -> 0.0821 | H18: =(VLOOKUP($B18,Daily!$A$1:$W$10000,H$1,FALSE))/100 -> 0.0823 | I18: =(VLOOKUP($B18,Daily!$A$1:$W$10000,I$1,FALSE))/100 -> 0.0825 | J18: =(VLOOKUP($B18,Daily!$A$1:$W$10000,J$1,FALSE))/100 -> 0.0828 | ... X18: =(VLOOKUP($B18,Daily!$A$1:$W$10000,X$1,FALSE))/100 -> 0.0857
A19: 40756 | B19: =WORKDAY(EOMONTH(A19,0)+1, -1)-1 -> 40785 | C19: =(VLOOKUP($B19,Daily!$A$1:$W$10000,C$1,FALSE))/100 -> 0.0812 | D19: =(VLOOKUP($B19,Daily!$A$1:$W$10000,D$1,FALSE))/100 -> 0.082 | E19: =(VLOOKUP($B19,Daily!$A$1:$W$10000,E$1,FALSE))/100 -> 0.0819 | F19: =(VLOOKUP($B19,Daily!$A$1:$W$10000,F$1,FALSE))/100 -> 0.0812 | G19: =(VLOOKUP($B19,Daily!$A$1:$W$10000,G$1,FALSE))/100 -> 0.0809 | H19: =(VLOOKUP($B19,Daily!$A$1:$W$10000,H$1,FALSE))/100 -> 0.0809 | I19: =(VLOOKUP($B19,Daily!$A$1:$W$10000,I$1,FALSE))/100 -> 0.0811 | J19: =(VLOOKUP($B19,Daily!$A$1:$W$10000,J$1,FALSE))/100 -> 0.0814 | ... X19: =(VLOOKUP($B19,Daily!$A$1:$W$10000,X$1,FALSE))/100 -> 0.085
A20: 40787 | B20: =WORKDAY(EOMONTH(A20,0)+1, -1)-1 -> 40815 | C20: =(VLOOKUP($B20,Daily!$A$1:$W$10000,C$1,FALSE))/100 -> 0.0824 | D20: =(VLOOKUP($B20,Daily!$A$1:$W$10000,D$1,FALSE))/100 -> 0.0819 | E20: =(VLOOKUP($B20,Daily!$A$1:$W$10000,E$1,FALSE))/100 -> 0.0815 | F20: =(VLOOKUP($B20,Daily!$A$1:$W$10000,F$1,FALSE))/100 -> 0.0811 | G20: =(VLOOKUP($B20,Daily!$A$1:$W$10000,G$1,FALSE))/100 -> 0.0811 | H20: =(VLOOKUP($B20,Daily!$A$1:$W$10000,H$1,FALSE))/100 -> 0.0813 | I20: =(VLOOKUP($B20,Daily!$A$1:$W$10000,I$1,FALSE))/100 -> 0.0816 | J20: =(VLOOKUP($B20,Daily!$A$1:$W$10000,J$1,FALSE))/100 -> 0.0819 | ... X20: =(VLOOKUP($B20,Daily!$A$1:$W$10000,X$1,FALSE))/100 -> 0.0852
A21: 40817 | B21: =WORKDAY(EOMONTH(A21,0)+1, -1) -> 40847 | C21: =(VLOOKUP($B21,Daily!$A$1:$W$10000,C$1,FALSE))/100 -> 0.0858 | D21: =(VLOOKUP($B21,Daily!$A$1:$W$10000,D$1,FALSE))/100 -> 0.085 | E21: =(VLOOKUP($B21,Daily!$A$1:$W$10000,E$1,FALSE))/100 -> 0.0849 | F21: =(VLOOKUP($B21,Daily!$A$1:$W$10000,F$1,FALSE))/100 -> 0.0853 | G21: =(VLOOKUP($B21,Daily!$A$1:$W$10000,G$1,FALSE))/100 -> 0.0859 | H21: =(VLOOKUP($B21,Daily!$A$1:$W$10000,H$1,FALSE))/100 -> 0.0864 | I21: =(VLOOKUP($B21,Daily!$A$1:$W$10000,I$1,FALSE))/100 -> 0.0867 | J21: =(VLOOKUP($B21,Daily!$A$1:$W$10000,J$1,FALSE))/100 -> 0.087 | ... X21: =(VLOOKUP($B21,Daily!$A$1:$W$10000,X$1,FALSE))/100 -> 0.0879
A22: 40848 | B22: =WORKDAY(EOMONTH(A22,0)+1, -1) -> 40877 | C22: =(VLOOKUP($B22,Daily!$A$1:$W$10000,C$1,FALSE))/100 -> 0.0875 | D22: =(VLOOKUP($B22,Daily!$A$1:$W$10000,D$1,FALSE))/100 -> 0.0854 | E22: =(VLOOKUP($B22,Daily!$A$1:$W$10000,E$1,FALSE))/100 -> 0.0847 | F22: =(VLOOKUP($B22,Daily!$A$1:$W$10000,F$1,FALSE))/100 -> 0.0845 | G22: =(VLOOKUP($B22,Daily!$A$1:$W$10000,G$1,FALSE))/100 -> 0.0846 | H22: =(VLOOKUP($B22,Daily!$A$1:$W$10000,H$1,FALSE))/100 -> 0.0848 | I22: =(VLOOKUP($B22,Daily!$A$1:$W$10000,I$1,FALSE))/100 -> 0.085 | J22: =(VLOOKUP($B22,Daily!$A$1:$W$10000,J$1,FALSE))/100 -> 0.0853 | ... X22: =(VLOOKUP($B22,Daily!$A$1:$W$10000,X$1,FALSE))/100 -> 0.0898
A23: 40878 | B23: =WORKDAY(EOMONTH(A23,0)+1, -1) -> 40907 | C23: =(VLOOKUP($B23,Daily!$A$1:$W$10000,C$1,FALSE))/100 -> 0.088 | D23: =(VLOOKUP($B23,Daily!$A$1:$W$10000,D$1,FALSE))/100 -> 0.0822 | E23: =(VLOOKUP($B23,Daily!$A$1:$W$10000,E$1,FALSE))/100 -> 0.0805 | F23: =(VLOOKUP($B23,Daily!$A$1:$W$10000,F$1,FALSE))/100 -> 0.0807 | G23: =(VLOOKUP($B23,Daily!$A$1:$W$10000,G$1,FALSE))/100 -> 0.0815 | H23: =(VLOOKUP($B23,Daily!$A$1:$W$10000,H$1,FALSE))/100 -> 0.0822 | I23: =(VLOOKUP($B23,Daily!$A$1:$W$10000,I$1,FALSE))/100 -> 0.0826 | J23: =(VLOOKUP($B23,Daily!$A$1:$W$10000,J$1,FALSE))/100 -> 0.083 | ... X23: =(VLOOKUP($B23,Daily!$A$1:$W$10000,X$1,FALSE))/100 -> 0.0872
A24: 40909 | B24: =WORKDAY(EOMONTH(A24,0)+1, -1) -> 40939 | C24: =(VLOOKUP($B24,Daily!$A$1:$W$10000,C$1,FALSE))/100 -> 0.085 | D24: =(VLOOKUP($B24,Daily!$A$1:$W$10000,D$1,FALSE))/100 -> 0.0857 | E24: =(VLOOKUP($B24,Daily!$A$1:$W$10000,E$1,FALSE))/100 -> 0.0837 | F24: =(VLOOKUP($B24,Daily!$A$1:$W$10000,F$1,FALSE))/100 -> 0.0811 | G24: =(VLOOKUP($B24,Daily!$A$1:$W$10000,G$1,FALSE))/100 -> 0.0799 | H24: =(VLOOKUP($B24,Daily!$A$1:$W$10000,H$1,FALSE))/100 -> 0.0796 | I24: =(VLOOKUP($B24,Daily!$A$1:$W$10000,I$1,FALSE))/100 -> 0.0798 | J24: =(VLOOKUP($B24,Daily!$A$1:$W$10000,J$1,FALSE))/100 -> 0.0802 | ... X24: =(VLOOKUP($B24,Daily!$A$1:$W$10000,X$1,FALSE))/100 -> 0.0853
A25: 40940 | B25: =WORKDAY(EOMONTH(A25,0)+1, -1) -> 40968 | C25: =(VLOOKUP($B25,Daily!$A$1:$W$10000,C$1,FALSE))/100 -> 0.0859 | D25: =(VLOOKUP($B25,Daily!$A$1:$W$10000,D$1,FALSE))/100 -> 0.0889 | E25: =(VLOOKUP($B25,Daily!$A$1:$W$10000,E$1,FALSE))/100 -> 0.0875 | F25: =(VLOOKUP($B25,Daily!$A$1:$W$10000,F$1,FALSE))/100 -> 0.0849 | G25: =(VLOOKUP($B25,Daily!$A$1:$W$10000,G$1,FALSE))/100 -> 0.0831 | H25: =(VLOOKUP($B25,Daily!$A$1:$W$10000,H$1,FALSE))/100 -> 0.0819 | I25: =(VLOOKUP($B25,Daily!$A$1:$W$10000,I$1,FALSE))/100 -> 0.0812 | J25: =(VLOOKUP($B25,Daily!$A$1:$W$10000,J$1,FALSE))/100 -> 0.0808 | ... X25: =(VLOOKUP($B25,Daily!$A$1:$W$10000,X$1,FALSE))/100 -> 0.085
A26: 40969 | B26: =WORKDAY(EOMONTH(A26,0)+1, -1) -> 40998 | C26: =(VLOOKUP($B26,Daily!$A$1:$W$10000,C$1,FALSE))/100 -> 0.0885 | D26: =(VLOOKUP($B26,Daily!$A$1:$W$10000,D$1,FALSE))/100 -> 0.0837 | E26: =(VLOOKUP($B26,Daily!$A$1:$W$10000,E$1,FALSE))/100 -> 0.0813 | F26: =(VLOOKUP($B26,Daily!$A$1:$W$10000,F$1,FALSE))/100 -> 0.0802 | G26: =(VLOOKUP($B26,Daily!$A$1:$W$10000,G$1,FALSE))/100 -> 0.0811 | H26: =(VLOOKUP($B26,Daily!$A$1:$W$10000,H$1,FALSE))/100 -> 0.0823 | I26: =(VLOOKUP($B26,Daily!$A$1:$W$10000,I$1,FALSE))/100 -> 0.0834 | J26: =(VLOOKUP($B26,Daily!$A$1:$W$10000,J$1,FALSE))/100 -> 0.0841 | ... X26: =(VLOOKUP($B26,Daily!$A$1:$W$10000,X$1,FALSE))/100 -> 0.0855
A27: 41000 | B27: =WORKDAY(EOMONTH(A27,0)+1, -1) -> 41029 | C27: =(VLOOKUP($B27,Daily!$A$1:$W$10000,C$1,FALSE))/100 -> 0.0842 | D27: =(VLOOKUP($B27,Daily!$A$1:$W$10000,D$1,FALSE))/100 -> 0.0804 | E27: =(VLOOKUP($B27,Daily!$A$1:$W$10000,E$1,FALSE))/100 -> 0.0791 | F27: =(VLOOKUP($B27,Daily!$A$1:$W$10000,F$1,FALSE))/100 -> 0.0796 | G27: =(VLOOKUP($B27,Daily!$A$1:$W$10000,G$1,FALSE))/100 -> 0.0809 | H27: =(VLOOKUP($B27,Daily!$A$1:$W$10000,H$1,FALSE))/100 -> 0.0821 | I27: =(VLOOKUP($B27,Daily!$A$1:$W$10000,I$1,FALSE))/100 -> 0.083 | J27: =(VLOOKUP($B27,Daily!$A$1:$W$10000,J$1,FALSE))/100 -> 0.0837 | ... X27: =(VLOOKUP($B27,Daily!$A$1:$W$10000,X$1,FALSE))/100 -> 0.0883
A28: 41030 | B28: =WORKDAY(EOMONTH(A28,0)+1, -1) -> 41060 | C28: =(VLOOKUP($B28,Daily!$A$1:$W$10000,C$1,FALSE))/100 -> 0.083 | D28: =(VLOOKUP($B28,Daily!$A$1:$W$10000,D$1,FALSE))/100 -> 0.0807 | E28: =(VLOOKUP($B28,Daily!$A$1:$W$10000,E$1,FALSE))/100 -> 0.0796 | F28: =(VLOOKUP($B28,Daily!$A$1:$W$10000,F$1,FALSE))/100 -> 0.0793 | G28: =(VLOOKUP($B28,Daily!$A$1:$W$10000,G$1,FALSE))/100 -> 0.0798 | H28: =(VLOOKUP($B28,Daily!$A$1:$W$10000,H$1,FALSE))/100 -> 0.0805 | I28: =(VLOOKUP($B28,Daily!$A$1:$W$10000,I$1,FALSE))/100 -> 0.0811 | J28: =(VLOOKUP($B28,Daily!$A$1:$W$10000,J$1,FALSE))/100 -> 0.0817 | ... X28: =(VLOOKUP($B28,Daily!$A$1:$W$10000,X$1,FALSE))/100 -> 0.0869
A29: 41061 | B29: =WORKDAY(EOMONTH(A29,0)+1, -1) -> 41089 | C29: =(VLOOKUP($B29,Daily!$A$1:$W$10000,C$1,FALSE))/100 -> 0.0838 | D29: =(VLOOKUP($B29,Daily!$A$1:$W$10000,D$1,FALSE))/100 -> 0.08 | E29: =(VLOOKUP($B29,Daily!$A$1:$W$10000,E$1,FALSE))/100 -> 0.0782 | F29: =(VLOOKUP($B29,Daily!$A$1:$W$10000,F$1,FALSE))/100 -> 0.0776 | G29: =(VLOOKUP($B29,Daily!$A$1:$W$10000,G$1,FALSE))/100 -> 0.0783 | H29: =(VLOOKUP($B29,Daily!$A$1:$W$10000,H$1,FALSE))/100 -> 0.0792 | I29: =(VLOOKUP($B29,Daily!$A$1:$W$10000,I$1,FALSE))/100 -> 0.08 | J29: =(VLOOKUP($B29,Daily!$A$1:$W$10000,J$1,FALSE))/100 -> 0.0806 | ... X29: =(VLOOKUP($B29,Daily!$A$1:$W$10000,X$1,FALSE))/100 -> 0.0858
A30: 41091 | B30: =WORKDAY(EOMONTH(A30,0)+1, -1) -> 41121 | C30: =(VLOOKUP($B30,Daily!$A$1:$W$10000,C$1,FALSE))/100 -> 0.0815 | D30: =(VLOOKUP($B30,Daily!$A$1:$W$10000,D$1,FALSE))/100 -> 0.0795 | E30: =(VLOOKUP($B30,Daily!$A$1:$W$10000,E$1,FALSE))/100 -> 0.0785 | F30: =(VLOOKUP($B30,Daily!$A$1:$W$10000,F$1,FALSE))/100 -> 0.078 | G30: =(VLOOKUP($B30,Daily!$A$1:$W$10000,G$1,FALSE))/100 -> 0.0784 | H30: =(VLOOKUP($B30,Daily!$A$1:$W$10000,H$1,FALSE))/100 -> 0.0791 | I30: =(VLOOKUP($B30,Daily!$A$1:$W$10000,I$1,FALSE))/100 -> 0.0797 | J30: =(VLOOKUP($B30,Daily!$A$1:$W$10000,J$1,FALSE))/100 -> 0.0803 | ... X30: =(VLOOKUP($B30,Daily!$A$1:$W$10000,X$1,FALSE))/100 -> 0.0855
A31: 41122 | B31: =WORKDAY(EOMONTH(A31,0)+1, -1) -> 41152 | C31: =(VLOOKUP($B31,Daily!$A$1:$W$10000,C$1,FALSE))/100 -> 0.0817 | D31: =(VLOOKUP($B31,Daily!$A$1:$W$10000,D$1,FALSE))/100 -> 0.08 | E31: =(VLOOKUP($B31,Daily!$A$1:$W$10000,E$1,FALSE))/100 -> 0.0791 | F31: =(VLOOKUP($B31,Daily!$A$1:$W$10000,F$1,FALSE))/100 -> 0.0786 | G31: =(VLOOKUP($B31,Daily!$A$1:$W$10000,G$1,FALSE))/100 -> 0.079 | H31: =(VLOOKUP($B31,Daily!$A$1:$W$10000,H$1,FALSE))/100 -> 0.0796 | I31: =(VLOOKUP($B31,Daily!$A$1:$W$10000,I$1,FALSE))/100 -> 0.0802 | J31: =(VLOOKUP($B31,Daily!$A$1:$W$10000,J$1,FALSE))/100 -> 0.0807 | ... X31: =(VLOOKUP($B31,Daily!$A$1:$W$10000,X$1,FALSE))/100 -> 0.0856
A32: 41153 | B32: =WORKDAY(EOMONTH(A32,0)+1, -1) -> 41180 | C32: =(VLOOKUP($B32,Daily!$A$1:$W$10000,C$1,FALSE))/100 -> 0.0806 | D32: =(VLOOKUP($B32,Daily!$A$1:$W$10000,D$1,FALSE))/100 -> 0.0793 | E32: =(VLOOKUP($B32,Daily!$A$1:$W$10000,E$1,FALSE))/100 -> 0.0787 | F32: =(VLOOKUP($B32,Daily!$A$1:$W$10000,F$1,FALSE))/100 -> 0.0785 | G32: =(VLOOKUP($B32,Daily!$A$1:$W$10000,G$1,FALSE))/100 -> 0.0788 | H32: =(VLOOKUP($B32,Daily!$A$1:$W$10000,H$1,FALSE))/100 -> 0.0793 | I32: =(VLOOKUP($B32,Daily!$A$1:$W$10000,I$1,FALSE))/100 -> 0.0797 | J32: =(VLOOKUP($B32,Daily!$A$1:$W$10000,J$1,FALSE))/100 -> 0.0801 | ... X32: =(VLOOKUP($B32,Daily!$A$1:$W$10000,X$1,FALSE))/100 -> 0.0843
... A37: 41306 | B37: =WORKDAY(EOMONTH(A37,0)+1, -1) -> 41333 | C37: =(VLOOKUP($B37,Daily!$A$1:$W$10000,C$1,FALSE))/100 -> 0.0802 | D37: =(VLOOKUP($B37,Daily!$A$1:$W$10000,D$1,FALSE))/100 -> 0.0786 | E37: =(VLOOKUP($B37,Daily!$A$1:$W$10000,E$1,FALSE))/100 -> 0.0775 | F37: =(VLOOKUP($B37,Daily!$A$1:$W$10000,F$1,FALSE))/100 -> 0.0767 | G37: =(VLOOKUP($B37,Daily!$A$1:$W$10000,G$1,FALSE))/100 -> 0.0765 | H37: =(VLOOKUP($B37,Daily!$A$1:$W$10000,H$1,FALSE))/100 -> 0.0767 | I37: =(VLOOKUP($B37,Daily!$A$1:$W$10000,I$1,FALSE))/100 -> 0.077 | J37: =(VLOOKUP($B37,Daily!$A$1:$W$10000,J$1,FALSE))/100 -> 0.0773 | ... X37: =(VLOOKUP($B37,Daily!$A$1:$W$10000,X$1,FALSE))/100 -> 0.0796
A38: 41334 | B38: =WORKDAY(EOMONTH(A38,0)+1, -1)-1 -> 41361 | C38: =(VLOOKUP($B38,Daily!$A$1:$W$10000,C$1,FALSE))/100 -> 0.0791 | D38: =(VLOOKUP($B38,Daily!$A$1:$W$10000,D$1,FALSE))/100 -> 0.0766 | E38: =(VLOOKUP($B38,Daily!$A$1:$W$10000,E$1,FALSE))/100 -> 0.076 | F38: =(VLOOKUP($B38,Daily!$A$1:$W$10000,F$1,FALSE))/100 -> 0.0762 | G38: =(VLOOKUP($B38,Daily!$A$1:$W$10000,G$1,FALSE))/100 -> 0.0767 | H38: =(VLOOKUP($B38,Daily!$A$1:$W$10000,H$1,FALSE))/100 -> 0.0771 | I38: =(VLOOKUP($B38,Daily!$A$1:$W$10000,I$1,FALSE))/100 -> 0.0775 | J38: =(VLOOKUP($B38,Daily!$A$1:$W$10000,J$1,FALSE))/100 -> 0.0778 | ... X38: =(VLOOKUP($B38,Daily!$A$1:$W$10000,X$1,FALSE))/100 -> 0.0811
A39: 41365 | B39: =WORKDAY(EOMONTH(A39,0)+1, -1) -> 41394 | C39: =(VLOOKUP($B39,Daily!$A$1:$W$10000,C$1,FALSE))/100 -> 0.0755 | D39: =(VLOOKUP($B39,Daily!$A$1:$W$10000,D$1,FALSE))/100 -> 0.0739 | E39: =(VLOOKUP($B39,Daily!$A$1:$W$10000,E$1,FALSE))/100 -> 0.0733 | F39: =(VLOOKUP($B39,Daily!$A$1:$W$10000,F$1,FALSE))/100 -> 0.0731 | G39: =(VLOOKUP($B39,Daily!$A$1:$W$10000,G$1,FALSE))/100 -> 0.0734 | H39: =(VLOOKUP($B39,Daily!$A$1:$W$10000,H$1,FALSE))/100 -> 0.074 | I39: =(VLOOKUP($B39,Daily!$A$1:$W$10000,I$1,FALSE))/100 -> 0.0745 | J39: =(VLOOKUP($B39,Daily!$A$1:$W$10000,J$1,FALSE))/100 -> 0.0751 | ... X39: =(VLOOKUP($B39,Daily!$A$1:$W$10000,X$1,FALSE))/100 -> 0.0788
A40: 41395 | B40: =WORKDAY(EOMONTH(A40,0)+1, -1) -> 41425 | C40: =(VLOOKUP($B40,Daily!$A$1:$W$10000,C$1,FALSE))/100 -> 0.0731 | D40: =(VLOOKUP($B40,Daily!$A$1:$W$10000,D$1,FALSE))/100 -> 0.0718 | E40: =(VLOOKUP($B40,Daily!$A$1:$W$10000,E$1,FALSE))/100 -> 0.0712 | F40: =(VLOOKUP($B40,Daily!$A$1:$W$10000,F$1,FALSE))/100 -> 0.071 | G40: =(VLOOKUP($B40,Daily!$A$1:$W$10000,G$1,FALSE))/100 -> 0.0714 | H40: =(VLOOKUP($B40,Daily!$A$1:$W$10000,H$1,FALSE))/100 -> 0.0718 | I40: =(VLOOKUP($B40,Daily!$A$1:$W$10000,I$1,FALSE))/100 -> 0.0722 | J40: =(VLOOKUP($B40,Daily!$A$1:$W$10000,J$1,FALSE))/100 -> 0.0725 | ... X40: =(VLOOKUP($B40,Daily!$A$1:$W$10000,X$1,FALSE))/100 -> 0.0742
A41: 41426 | B41: =WORKDAY(EOMONTH(A41,0)+1, -1) -> 41453 | C41: =(VLOOKUP($B41,Daily!$A$1:$W$10000,C$1,FALSE))/100 -> 0.0738 | D41: =(VLOOKUP($B41,Daily!$A$1:$W$10000,D$1,FALSE))/100 -> 0.0739 | E41: =(VLOOKUP($B41,Daily!$A$1:$W$10000,E$1,FALSE))/100 -> 0.074 | F41: =(VLOOKUP($B41,Daily!$A$1:$W$10000,F$1,FALSE))/100 -> 0.0742 | G41: =(VLOOKUP($B41,Daily!$A$1:$W$10000,G$1,FALSE))/100 -> 0.0743 | H41: =(VLOOKUP($B41,Daily!$A$1:$W$10000,H$1,FALSE))/100 -> 0.0745 | I41: =(VLOOKUP($B41,Daily!$A$1:$W$10000,I$1,FALSE))/100 -> 0.0747 | J41: =(VLOOKUP($B41,Daily!$A$1:$W$10000,J$1,FALSE))/100 -> 0.0749 | ... X41: =(VLOOKUP($B41,Daily!$A$1:$W$10000,X$1,FALSE))/100 -> 0.0772
A42: 41456 | B42: =WORKDAY(EOMONTH(A42,0)+1, -1) -> 41486 | C42: =(VLOOKUP($B42,Daily!$A$1:$W$10000,C$1,FALSE))/100 -> 0.109 | D42: =(VLOOKUP($B42,Daily!$A$1:$W$10000,D$1,FALSE))/100 -> 0.0999 | E42: =(VLOOKUP($B42,Daily!$A$1:$W$10000,E$1,FALSE))/100 -> 0.0936 | F42: =(VLOOKUP($B42,Daily!$A$1:$W$10000,F$1,FALSE))/100 -> 0.0886 | G42: =(VLOOKUP($B42,Daily!$A$1:$W$10000,G$1,FALSE))/100 -> 0.0864 | H42: =(VLOOKUP($B42,Daily!$A$1:$W$10000,H$1,FALSE))/100 -> 0.0852 | I42: =(VLOOKUP($B42,Daily!$A$1:$W$10000,I$1,FALSE))/100 -> 0.0845 | J42: =(VLOOKUP($B42,Daily!$A$1:$W$10000,J$1,FALSE))/100 -> 0.0841 | ... X42: =(VLOOKUP($B42,Daily!$A$1:$W$10000,X$1,FALSE))/100 -> 0.0859
A43: 41487 | B43: =WORKDAY(EOMONTH(A43,0)+1, -1) -> 41516 | C43: =(VLOOKUP($B43,Daily!$A$1:$W$10000,C$1,FALSE))/100 -> 0.105 | D43: =(VLOOKUP($B43,Daily!$A$1:$W$10000,D$1,FALSE))/100 -> 0.1048 | E43: =(VLOOKUP($B43,Daily!$A$1:$W$10000,E$1,FALSE))/100 -> 0.0957 | F43: =(VLOOKUP($B43,Daily!$A$1:$W$10000,F$1,FALSE))/100 -> 0.09 | G43: =(VLOOKUP($B43,Daily!$A$1:$W$10000,G$1,FALSE))/100 -> 0.0889 | H43: =(VLOOKUP($B43,Daily!$A$1:$W$10000,H$1,FALSE))/100 -> 0.0887 | I43: =(VLOOKUP($B43,Daily!$A$1:$W$10000,I$1,FALSE))/100 -> 0.0889 | J43: =(VLOOKUP($B43,Daily!$A$1:$W$10000,J$1,FALSE))/100 -> 0.0891 | ... X43: =(VLOOKUP($B43,Daily!$A$1:$W$10000,X$1,FALSE))/100 -> 0.09
A44: 41518 | B44: =WORKDAY(EOMONTH(A44,0)+1, -1) -> 41547 | C44: =(VLOOKUP($B44,Daily!$A$1:$W$10000,C$1,FALSE))/100 -> 0.0974 | D44: =(VLOOKUP($B44,Daily!$A$1:$W$10000,D$1,FALSE))/100 -> 0.0907 | E44: =(VLOOKUP($B44,Daily!$A$1:$W$10000,E$1,FALSE))/100 -> 0.0871 | F44: =(VLOOKUP($B44,Daily!$A$1:$W$10000,F$1,FALSE))/100 -> 0.0846 | G44: =(VLOOKUP($B44,Daily!$A$1:$W$10000,G$1,FALSE))/100 -> 0.0848 | H44: =(VLOOKUP($B44,Daily!$A$1:$W$10000,H$1,FALSE))/100 -> 0.0858 | I44: =(VLOOKUP($B44,Daily!$A$1:$W$10000,I$1,FALSE))/100 -> 0.0868 | J44: =(VLOOKUP($B44,Daily!$A$1:$W$10000,J$1,FALSE))/100 -> 0.0878 | ... X44: =(VLOOKUP($B44,Daily!$A$1:$W$10000,X$1,FALSE))/100 -> 0.0919
...

Sheet Macro Factors
A1: Date | B1: Inflation | C1: IIP.ogap
A2: 40389 | B2: 0.1286 | C2: 0
A3: 40421 | B3: 0.1066 | C3: 0
A4: 40450 | B4: 0.0942 | C4: 0
A5: 40480 | B5: 0.0936 | C5: 0
A6: 40512 | B6: 0.0926 | C6: 0
A7: 40543 | B7: 0.08 | C7: 0
A8: 40574 | B8: 0.0905 | C8: 0
A9: 40602 | B9: 0.0855 | C9: 0
A10: 40633 | B10: 0.0848 | C10: 0
A11: 40662 | B11: 0.0848 | C11: 0
A12: 40694 | B12: 0.0927 | C12: 0
A13: 40724 | B13: 0.0888 | C13: 0
... A184: 45930 | B184: 0.0207 | C184: -0.0042393584
A185: 45961 | B185: 0.0144 | C185: =C184 -> -0.0042393584
A186: 45991 | B186: 0.0025 | C186: 0
A187: 46022 | B187: 0.017 | C187: 0
A188: 46053 | B188: 0.0274 | C188: 0
A189: 46081 | B189: 0.0321 | C189: 0
A190: 46111 | B190: 0.034 | C190: 0
A191: 46142 | B191: 0.0348 | C191: 0

Sheet Sheet1
A1: Month | B1: CPI-C Index | G1: Old Spliced series
A2: 36892 | B2: 55.5 | G2: 0.1286
A3: 36923 | B3: 55.4 | G3: 0.1066
A4: 36951 | B4: 55.7 | G4: 0.0942
A5: 36982 | B5: 56.1 | G5: 0.0936
A6: 37012 | B6: 56.5 | G6: 0.0926
A7: 37043 | B7: 57.1 | G7: 0.08
A8: 37073 | B8: 57.8 | G8: 0.0905
A9: 37104 | B9: 58.2 | G9: 0.0855
A10: 37135 | B10: 58 | G10: 0.0848
A11: 37165 | B11: 58.6 | G11: 0.0848
A12: 37196 | B12: 59 | G12: 0.0927
A13: 37226 | B13: 58.8 | G13: 0.0888
A14: 37257 | B14: 58.6 | C14: =B14/B2 - 1 -> 0.055855856 | G14: 0.0862
A15: 37288 | B15: 58.5 | C15: =B15/B3 - 1 -> 0.055956679 | G15: 0.0766
A16: 37316 | B16: 58.9 | C16: =B16/B4 - 1 -> 0.057450628 | G16: 0.0863
A17: 37347 | B17: 59.2 | C17: =B17/B5 - 1 -> 0.055258467 | G17: 0.0925
A18: 37377 | B18: 59.6 | C18: =B18/B6 - 1 -> 0.054867257 | G18: 0.092
A19: 37408 | B19: 60.2 | C19: =B19/B7 - 1 -> 0.054290718 | G19: 0.0907
A20: 37438 | B20: 60.8 | C20: =B20/B8 - 1 -> 0.051903114 | G20: 0.0691
A21: 37469 | B21: 61.1 | C21: =B21/B9 - 1 -> 0.049828179 | G21: 0.062569832
A22: 37500 | B22: 61.2 | C22: =B22/B10 - 1 -> 0.055172414 | G22: 0.080316742
A23: 37530 | B23: 61.5 | C23: =B23/B11 - 1 -> 0.049488055 | G23: 0.090497738
A24: 37561 | B24: 61.7 | C24: =B24/B12 - 1 -> 0.045762712 | G24: 0.097643098
A25: 37591 | B25: 61.3 | C25: =B25/B13 - 1 -> 0.042517007 | G25: 0.097995546
... A43: 38139 | B43: 65.1 | C43: =B43/B31 - 1 -> 0.033333333 | G43: 0.11505273
A44: 38169 | B44: 65.6 | C44: =B44/B32 - 1 -> 0.033070866
A45: 38200 | B45: 66.2 | C45: =B45/B33 - 1 -> 0.049128368
A46: 38231 | B46: 66.3 | C46: =B46/B34 - 1 -> 0.049050633
A47: 38261 | B47: 66.8 | C47: =B47/B35 - 1 -> 0.04866562
A48: 38292 | B48: 66.6 | C48: =B48/B36 - 1 -> 0.043887147
A49: 38322 | B49: 66.1 | C49: =B49/B37 - 1 -> 0.037676609
A50: 38353 | B50: 66.6 | C50: =B50/B38 - 1 -> 0.043887147
A51: 38384 | B51: 66.6 | C51: =B51/B39 - 1 -> 0.043887147
A52: 38412 | B52: 66.6 | C52: =B52/B40 - 1 -> 0.042253521
A53: 38443 | B53: 67.1 | C53: =B53/B41 - 1 -> 0.046801872
A54: 38473 | B54: 66.7 | C54: =B54/B42 - 1 -> 0.03250774
A55: 38504 | B55: 66.8 | C55: =B55/B43 - 1 -> 0.026113671
... A157: 41609 | B157: 138 | C157: =B157/B145 - 1 -> 0.098726115

Sheet Daily_old
A1: Date | B1: 3m | C1: 6m | D1: 12m | E1: 24m | F1: 36m | G1: 48m | H1: 60m | I1: 72m | J1: 84m | K1: 96m | L1: 108m | M1: 120m | N1: 132m | O1: 144m | P1: 156m | Q1: 168m | R1: 180m | S1: 192m | T1: 204m | U1: 216m | V1: 228m | W1: 240m
A2: 40273 | B2: 2.46 | C2: 4.56 | D2: 5.68 | E2: 6.59 | F2: 6.9 | G2: 7.08 | H2: 7.25 | I2: 7.41 | J2: 7.55 | K2: 7.69 | L2: 7.8 | M2: 7.9 | N2: 7.98 | O2: 8.06 | P2: 8.12 | Q2: 8.17 | R2: 8.22 | S2: 8.26 | T2: 8.3 | U2: 8.33 | V2: 8.36 | W2: 8.38
A3: 40274 | B3: 2.9 | C3: 4.26 | D3: 5.14 | E3: 6.14 | F3: 6.67 | G3: 7.01 | H3: 7.26 | I3: 7.46 | J3: 7.62 | K3: 7.76 | L3: 7.87 | M3: 7.97 | N3: 8.05 | O3: 8.12 | P3: 8.18 | Q3: 8.23 | R3: 8.28 | S3: 8.32 | T3: 8.35 | U3: 8.38 | V3: 8.41 | W3: 8.44
A4: 40275 | B4: 2.92 | C4: 4.22 | D4: 5.08 | E4: 6.07 | F4: 6.61 | G4: 6.97 | H4: 7.23 | I4: 7.43 | J4: 7.6 | K4: 7.74 | L4: 7.85 | M4: 7.95 | N4: 8.03 | O4: 8.1 | P4: 8.16 | Q4: 8.21 | R4: 8.26 | S4: 8.3 | T4: 8.33 | U4: 8.37 | V4: 8.39 | W4: 8.42
A5: 40276 | B5: 2.74 | C5: 4.44 | D5: 5.14 | E5: 5.88 | F5: 6.43 | G5: 6.87 | H5: 7.2 | I5: 7.45 | J5: 7.65 | K5: 7.79 | L5: 7.91 | M5: 8.01 | N5: 8.09 | O5: 8.15 | P5: 8.21 | Q5: 8.25 | R5: 8.29 | S5: 8.33 | T5: 8.36 | U5: 8.39 | V5: 8.41 | W5: 8.44
A6: 40277 | B6: 2.33 | C6: 4.43 | D6: 5.31 | E6: 6.15 | F6: 6.68 | G6: 7.07 | H6: 7.37 | I6: 7.58 | J6: 7.75 | K6: 7.88 | L6: 7.98 | M6: 8.06 | N6: 8.13 | O6: 8.18 | P6: 8.23 | Q6: 8.27 | R6: 8.3 | S6: 8.34 | T6: 8.36 | U6: 8.39 | V6: 8.41 | W6: 8.43
A7: 40280 | B7: 2.52 | C7: 4.17 | D7: 5.24 | E7: 6.41 | F7: 6.99 | G7: 7.33 | H7: 7.56 | I7: 7.73 | J7: 7.87 | K7: 7.97 | L7: 8.06 | M7: 8.13 | N7: 8.19 | O7: 8.24 | P7: 8.28 | Q7: 8.32 | R7: 8.35 | S7: 8.38 | T7: 8.41 | U7: 8.43 | V7: 8.45 | W7: 8.47
A8: 40281 | B8: 3 | C8: 4.24 | D8: 5.12 | E8: 6.23 | F8: 6.86 | G8: 7.25 | H8: 7.51 | I8: 7.7 | J8: 7.84 | K8: 7.94 | L8: 8.03 | M8: 8.09 | N8: 8.15 | O8: 8.2 | P8: 8.23 | Q8: 8.27 | R8: 8.3 | S8: 8.32 | T8: 8.34 | U8: 8.36 | V8: 8.38 | W8: 8.4
A9: 40283 | B9: 3.25 | C9: 4.42 | D9: 5.2 | E9: 6.14 | F9: 6.69 | G9: 7.08 | H9: 7.38 | I9: 7.61 | J9: 7.81 | K9: 7.96 | L9: 8.08 | M9: 8.18 | N9: 8.26 | O9: 8.32 | P9: 8.36 | Q9: 8.4 | R9: 8.42 | S9: 8.44 | T9: 8.46 | U9: 8.47 | V9: 8.47 | W9: 8.47
A10: 40284 | B10: 3.13 | C10: 4.47 | D10: 5.34 | E10: 6.34 | F10: 6.88 | G10: 7.24 | H10: 7.49 | I10: 7.68 | J10: 7.82 | K10: 7.94 | L10: 8.03 | M10: 8.1 | N10: 8.16 | O10: 8.21 | P10: 8.26 | Q10: 8.29 | R10: 8.33 | S10: 8.35 | T10: 8.38 | U10: 8.4 | V10: 8.42 | W10: 8.44
A11: 40287 | B11: 3.2 | C11: 4.52 | D11: 5.32 | E11: 6.26 | F11: 6.83 | G11: 7.23 | H11: 7.51 | I11: 7.71 | J11: 7.86 | K11: 7.98 | L11: 8.08 | M11: 8.15 | N11: 8.21 | O11: 8.26 | P11: 8.31 | Q11: 8.34 | R11: 8.37 | S11: 8.4 | T11: 8.43 | U11: 8.45 | V11: 8.47 | W11: 8.49
A12: 40288 | B12: 3.44 | C12: 4.46 | D12: 5.17 | E12: 6.1 | F12: 6.71 | G12: 7.13 | H12: 7.43 | I12: 7.65 | J12: 7.82 | K12: 7.94 | L12: 8.04 | M12: 8.12 | N12: 8.19 | O12: 8.24 | P12: 8.29 | Q12: 8.33 | R12: 8.36 | S12: 8.39 | T12: 8.42 | U12: 8.44 | V12: 8.46 | W12: 8.48
A13: 40289 | B13: 3.21 | C13: 4.42 | D13: 5.12 | E13: 5.98 | F13: 6.58 | G13: 7.01 | H13: 7.33 | I13: 7.57 | J13: 7.75 | K13: 7.89 | L13: 8 | M13: 8.09 | N13: 8.16 | O13: 8.22 | P13: 8.27 | Q13: 8.32 | R13: 8.35 | S13: 8.39 | T13: 8.42 | U13: 8.44 | V13: 8.47 | W13: 8.49
... A3869: 46122 | B3869: 5.22 | C3869: 5.39 | D3869: 5.55 | E3869: 5.84 | F3869: 6.08 | G3869: 6.3 | H3869: 6.48 | I3869: 6.65 | J3869: 6.79 | K3869: 6.91 | L3869: 7.02 | M3869: 7.12 | N3869: 7.2 | O3869: 7.28 | P3869: 7.35 | Q3869: 7.41 | R3869: 7.46 | S3869: 7.51 | T3869: 7.55 | U3869: 7.59 | V3869: 7.62 | W3869: 7.65

Sheet Daily_with OIS
A1: Date | B1: 3m | C1: 6m | D1: 12m | E1: 24m | F1: 36m | G1: 48m | H1: 60m | I1: 72m | J1: 84m | K1: 96m | L1: 108m | M1: 120m | N1: 132m | O1: 144m | P1: 156m | Q1: 168m | R1: 180m | S1: 192m | T1: 204m | U1: 216m | V1: 228m | W1: 240m
A2: 40273 | B2: 4.05 | C2: 4.405 | D2: 5.68 | E2: 6.59 | F2: 6.9 | G2: 7.08 | H2: 7.25 | I2: 7.41 | J2: 7.55 | K2: 7.69 | L2: 7.8 | M2: 7.9 | N2: 7.98 | O2: 8.06 | P2: 8.12 | Q2: 8.17 | R2: 8.22 | S2: 8.26 | T2: 8.3 | U2: 8.33 | V2: 8.36 | W2: 8.38
A3: 40274 | B3: 4.05 | C3: 4.4 | D3: 5.14 | E3: 6.14 | F3: 6.67 | G3: 7.01 | H3: 7.26 | I3: 7.46 | J3: 7.62 | K3: 7.76 | L3: 7.87 | M3: 7.97 | N3: 8.05 | O3: 8.12 | P3: 8.18 | Q3: 8.23 | R3: 8.28 | S3: 8.32 | T3: 8.35 | U3: 8.38 | V3: 8.41 | W3: 8.44
A4: 40275 | B4: 4.05 | C4: 4.38 | D4: 5.08 | E4: 6.07 | F4: 6.61 | G4: 6.97 | H4: 7.23 | I4: 7.43 | J4: 7.6 | K4: 7.74 | L4: 7.85 | M4: 7.95 | N4: 8.03 | O4: 8.1 | P4: 8.16 | Q4: 8.21 | R4: 8.26 | S4: 8.3 | T4: 8.33 | U4: 8.37 | V4: 8.39 | W4: 8.42
A5: 40276 | B5: 4.055 | C5: 4.36 | D5: 5.14 | E5: 5.88 | F5: 6.43 | G5: 6.87 | H5: 7.2 | I5: 7.45 | J5: 7.65 | K5: 7.79 | L5: 7.91 | M5: 8.01 | N5: 8.09 | O5: 8.15 | P5: 8.21 | Q5: 8.25 | R5: 8.29 | S5: 8.33 | T5: 8.36 | U5: 8.39 | V5: 8.41 | W5: 8.44
A6: 40277 | B6: 4.1 | C6: 4.435 | D6: 5.31 | E6: 6.15 | F6: 6.68 | G6: 7.07 | H6: 7.37 | I6: 7.58 | J6: 7.75 | K6: 7.88 | L6: 7.98 | M6: 8.06 | N6: 8.13 | O6: 8.18 | P6: 8.23 | Q6: 8.27 | R6: 8.3 | S6: 8.34 | T6: 8.36 | U6: 8.39 | V6: 8.41 | W6: 8.43
A7: 40280 | B7: 4.15 | C7: 4.46 | D7: 5.24 | E7: 6.41 | F7: 6.99 | G7: 7.33 | H7: 7.56 | I7: 7.73 | J7: 7.87 | K7: 7.97 | L7: 8.06 | M7: 8.13 | N7: 8.19 | O7: 8.24 | P7: 8.28 | Q7: 8.32 | R7: 8.35 | S7: 8.38 | T7: 8.41 | U7: 8.43 | V7: 8.45 | W7: 8.47
A8: 40281 | B8: 4.15 | C8: 4.46 | D8: 5.12 | E8: 6.23 | F8: 6.86 | G8: 7.25 | H8: 7.51 | I8: 7.7 | J8: 7.84 | K8: 7.94 | L8: 8.03 | M8: 8.09 | N8: 8.15 | O8: 8.2 | P8: 8.23 | Q8: 8.27 | R8: 8.3 | S8: 8.32 | T8: 8.34 | U8: 8.36 | V8: 8.38 | W8: 8.4
A9: 40283 | B9: 4.225 | C9: 4.52 | D9: 5.2 | E9: 6.14 | F9: 6.69 | G9: 7.08 | H9: 7.38 | I9: 7.61 | J9: 7.81 | K9: 7.96 | L9: 8.08 | M9: 8.18 | N9: 8.26 | O9: 8.32 | P9: 8.36 | Q9: 8.4 | R9: 8.42 | S9: 8.44 | T9: 8.46 | U9: 8.47 | V9: 8.47 | W9: 8.47
A10: 40284 | B10: 4.2 | C10: 4.52 | D10: 5.34 | E10: 6.34 | F10: 6.88 | G10: 7.24 | H10: 7.49 | I10: 7.68 | J10: 7.82 | K10: 7.94 | L10: 8.03 | M10: 8.1 | N10: 8.16 | O10: 8.21 | P10: 8.26 | Q10: 8.29 | R10: 8.33 | S10: 8.35 | T10: 8.38 | U10: 8.4 | V10: 8.42 | W10: 8.44
A11: 40287 | B11: 4.225 | C11: 4.52 | D11: 5.32 | E11: 6.26 | F11: 6.83 | G11: 7.23 | H11: 7.51 | I11: 7.71 | J11: 7.86 | K11: 7.98 | L11: 8.08 | M11: 8.15 | N11: 8.21 | O11: 8.26 | P11: 8.31 | Q11: 8.34 | R11: 8.37 | S11: 8.4 | T11: 8.43 | U11: 8.45 | V11: 8.47 | W11: 8.49
A12: 40288 | B12: 4.05 | C12: 4.35 | D12: 5.17 | E12: 6.1 | F12: 6.71 | G12: 7.13 | H12: 7.43 | I12: 7.65 | J12: 7.82 | K12: 7.94 | L12: 8.04 | M12: 8.12 | N12: 8.19 | O12: 8.24 | P12: 8.29 | Q12: 8.33 | R12: 8.36 | S12: 8.39 | T12: 8.42 | U12: 8.44 | V12: 8.46 | W12: 8.48
A13: 40289 | B13: 4.1 | C13: 4.325 | D13: 5.12 | E13: 5.98 | F13: 6.58 | G13: 7.01 | H13: 7.33 | I13: 7.57 | J13: 7.75 | K13: 7.89 | L13: 8 | M13: 8.09 | N13: 8.16 | O13: 8.22 | P13: 8.27 | Q13: 8.32 | R13: 8.35 | S13: 8.39 | T13: 8.42 | U13: 8.44 | V13: 8.47 | W13: 8.49
... A3869: 46122 | B3869: 5.4 | C3869: 5.52 | D3869: 5.55 | E3869: 5.84 | F3869: 6.08 | G3869: 6.3 | H3869: 6.48 | I3869: 6.65 | J3869: 6.79 | K3869: 6.91 | L3869: 7.02 | M3869: 7.12 | N3869: 7.2 | O3869: 7.28 | P3869: 7.35 | Q3869: 7.41 | R3869: 7.46 | S3869: 7.51 | T3869: 7.55 | U3869: 7.59 | V3869: 7.62 | W3869: 7.65

Sheet Long_data
A1: Date | B1: 3m | C1: 6m | D1: 12m | E1: 24m | F1: 36m | G1: 48m | H1: 60m | I1: 72m | J1: 84m | K1: 96m | L1: 108m | M1: 120m
A2: 36529 | B2: 9.97 | C2: 9.99 | D2: 10.092 | E2: 10.303 | F2: 10.31 | G2: 10.648 | H2: 10.712 | I2: 10.873 | J2: 11.044 | K2: 11.178 | L2: 11.436 | M2: 11.534
A3: 36530 | B3: 9.93 | C3: 9.95 | D3: 10.052 | E3: 10.348 | F3: 10.353 | G3: 10.691 | H3: 10.754 | I3: 10.916 | J3: 11.086 | K3: 11.22 | L3: 11.479 | M3: 11.576
A4: 36531 | B4: 9.96 | C4: 9.98 | D4: 10.072 | E4: 10.378 | F4: 10.372 | G4: 10.722 | H4: 10.785 | I4: 10.947 | J4: 11.117 | K4: 11.251 | L4: 11.494 | M4: 11.609
A5: 36532 | B5: 9.96 | C5: 9.98 | D5: 10.072 | E5: 10.452 | F5: 10.445 | G5: 10.759 | H5: 10.798 | I5: 10.96 | J5: 11.132 | K5: 11.267 | L5: 11.51 | M5: 11.626
A6: 36535 | B6: 10.06 | C6: 10.08 | D6: 10.172 | E6: 10.415 | F6: 10.41 | G6: 10.725 | H6: 10.764 | I6: 10.927 | J6: 11.099 | K6: 11.234 | L6: 11.477 | M6: 11.593
A7: 36536 | B7: 10.07 | C7: 10.09 | D7: 10.182 | E7: 10.425 | F7: 10.364 | G7: 10.716 | H7: 10.742 | I7: 10.932 | J7: 11.132 | K7: 11.19 | L7: 11.45 | M7: 11.566
A8: 36537 | B8: 9.95 | C8: 9.97 | D8: 10.062 | E8: 10.485 | F8: 10.41 | G8: 10.713 | H8: 10.753 | I8: 10.936 | J8: 11.128 | K8: 11.187 | L8: 11.447 | M8: 11.617
A9: 36538 | B9: 10.05 | C9: 10.07 | D9: 10.162 | E9: 10.458 | F9: 10.441 | G9: 10.709 | H9: 10.749 | I9: 10.933 | J9: 11.126 | K9: 11.184 | L9: 11.445 | M9: 11.615
A10: 36539 | B10: 10.05 | C10: 10.07 | D10: 10.162 | E10: 10.415 | F10: 10.432 | G10: 10.7 | H10: 10.74 | I10: 10.924 | J10: 11.116 | K10: 11.175 | L10: 11.435 | M10: 11.57
A11: 36542 | B11: 9.87 | C11: 9.85 | D11: 9.932 | E11: 10.217 | F11: 10.256 | G11: 10.463 | H11: 10.604 | I11: 10.712 | J11: 10.826 | K11: 10.963 | L11: 11.22 | M11: 11.354
